Workbook

Sheet Form responses 1
A1: Timestamp | B1: Date | C1: Time | D1: Type Of Meeting | E1: Name of Restaurant ? | F1: Seating Capacity | G1: AOV | H1: POS | I1: Daily Revenue? | J1: Kind of Restaurant | K1: Restaurant Live on | L1: Claimed Margins (Competition) | M1: Expected Margins (Caps) | N1: No.of Branches? | O1: Type of Ownership | P1: GST | Q1: FSSAI | R1: Labour License | S1: Google Map Business link | T1: Restaurant ID | U1: Name (POC-1) | V1: Contact Number (POC-1) | W1: Email- ID (POC-1) | X1: Name (POC-2) | Y1: Contact Number (POC-2) | Z1: Email- ID (POC-2) | AA1: Do you want to Submit Documents | AB1: FSSAI Number | AC1: FSSAI 2 | AD1: GST Number | AE1: GST 2 | AF1: PAN Number | AG1: PAN Card | AH1: Labour License Number | AI1: Labour License 2 | AJ1: Menu (Image) | AK1: Bank Account Proof | AL1: Account Number | AM1: IFSC | AN1: Name on Bank Account | AO1: Owner Name | AP1: Owner Contact Number | AQ1: Owner Email address | AR1: Legal Entity Name | AS1: Onboarding Done | AT1: Remarks(Comments) | AU1: Follow Up Meeting Required? | AV1: Meeting agenda for follow up | AW1: Points to be prepared | AX1: Meeting Date | AY1: Meeting Time | AZ1: Email address | BA1: Cold Walk/ Scheduled | BB1: POC Available | BC1: Manager Name | BD1: Manager Contact Details | BE1: Manager Email ID | BF1: Manager Contact Number | BG1: Manager Email ID 2 | BH1: Caps Magin % | BI1: Additional 2% Distance Margin | BJ1: Restaurant Open Time | BK1: Restaurant Close Time | BL1: Daily Online Orders | BM1: Restaurant Address | BN1: Cluster | BO1: Name of Restaurant Walk | BP1: Name of Restaurant | BQ1: Name of Ra | BR1: Restaurant Name Concat
A4: 46056.702 | B4: 44577 | C4: 0.42430556 | D4: Growth Meeting | T4: 5823694 | U4: sandeep | V4: 916679555 | W4: parul986@gmail | X4: amit | Y4: 7896541232 | Z4: parul@gmail | AA4: Yes | AB4: 3589795 | AC4: https://drive.google.com/open?id=1K2GAYdf9j8OoeRQJN7a2rrWNqrJv-Yr8 | AD4: 6954865895 | AE4: https://drive.google.com/open?id=1Xrc3uPOk64pgUM1gMvRHq-hhYc6pYKJT | AF4: 685654hgu | AG4: https://drive.google.com/open?id=1P8o5u-wkGayDLIcyTArlaMzpPcBL8IP1 | AH4: 5484581245 | AI4: https://drive.google.com/open?id=1zOmxq565qkkMqqCAFCaCRWzjb7i60OTF | AJ4: https://drive.google.com/open?id=1qsXvdJuct7_aToPR8ThIMJcmid9TRtyr | AL4: 54946489461649 | AM4: 949464bguhb | AN4: icici | AO4: jihughyfu | AP4: 64946165597 | AQ4: jhgyfyf2@GMAIL,COM | AR4: HVTFUGYFYGJH | AS4: Yes | AU4: Yes | AV4: Document Collection | AW4: KBUHIH | AX4: 35098 | AY4: 0.42430556 | AZ4: TEST | BR4: =Concatenate(BQ4,BP4,BO4,E4,T4) -> 5823694
A5: 46056.798 | B5: 46056 | C5: 0.66666667 | D5: Intro Meeting | E5: Bhuvan’s Kitchen | F5: 85 | G5: 250 | H5: OrderMatic | I5: 50000 | J5: Tier-2 (AOV <400) | K5: None | L5: 28 | M5: 20 | N5: 1 | O5: Prop | P5: Yes | Q5: Active | R5: Not Applied | S5: https://maps.app.goo.gl/QukQHejyepep1eaLA?g_st=ic | U5: Rama Rao | V5: 9030611616 | W5: Bhuvan’skitchen25@gmail.com | AA5: Yes | AB5: 20251226108111377 | AC5: https://drive.google.com/open?id=1zQ8cp3_66Bhden1m6eXDLNsshBt8JXb3 | AL5: 50200102000231 | AM5: HDFC0010090 | AN5: HDFC Bank | AO5: Rama Rao | AP5: 9030611616 | AQ5: bhuvanskitchen25@gmail.com | AR5: Bhuvan’s Kitchen | AS5: Yes | AT5: Res has been onboarded | AU5: No | AZ5: manasa.chigurupati@capsdelivery.com | BR5: =Concatenate(BQ5,BP5,BO5,E5,T5) -> Bhuvan’s Kitchen
A6: 46056.803 | B6: 46056 | C6: 0.64583333 | D6: Follow up | T6: 12345578 | U6: Mohammed Amir | V6: 9949814600 | W6: na | AA6: No | AU6: Yes | AV6: Contract Signing | AX6: 46057 | AY6: 0.45833333 | AZ6: sumadhur.mummadi@capsdelivery.com | BR6: =Concatenate(BQ6,BP6,BO6,E6,T6) -> 12345578
A7: 46057.379 | B7: 46056 | C7: 0.75 | D7: Intro Meeting | E7: Bhojanams & Birynis | F7: 30 | G7: 500 | H7: NA | I7: 24 | J7: Tier-2 (AOV <400) | K7: Zomato | N7: 1 | O7: Prop | P7: Yes | Q7: Active | R7: Yes | S7: yes | U7: Shesha sai | V7: 9052592437 | W7: sheshasai@gmail.com | AA7: Yes | AB7: 13619013001993 | AC7: https://drive.google.com/open?id=1jDd9udZkiYFM95E6qDnBXxB9dZAPA3Q6 | AD7: 36AAHFi2620K1ZF | AE7: https://drive.google.com/open?id=1wmAzfgRO6AUexNEcncft5vbltGIV8av4 | AK7: https://drive.google.com/open?id=13qbsLsi98K74BchvdcD_7-swJp4EtkeO | AL7: 10192341683 | AM7: IDFB00B0231 | AN7: IDFC | AO7: SHESHA SAI | AP7: 9052592437 | AR7: INVENCES FOODS | AS7: Yes | AT7: PARTNER ON BOARDED | AU7: No | AV7: Document Collection | AX7: 46056 | AY7: 0.84722222 | AZ7: chanakya.inugala@capsdelivery.com | BR7: =Concatenate(BQ7,BP7,BO7,E7,T7) -> Bhojanams & Birynis
A8: 46057.397 | B8: 46055 | C8: 0.23958333 | D8: Intro Meeting | E8: Sunrise Business Hotel | F8: 100 | G8: 300 | H8: Own | I8: 50000 | J8: Tier-2 (AOV <400) | K8: Swiggy, Zomato | N8: 1 | O8: Partnership | P8: Yes | Q8: Active | R8: Yes | S8: https://maps.app.goo.gl/U96V4tJ8v4oih7cF9 | U8: Venkat Lingam | V8: 8989873636 | W8: bowlrise.srnagar@gmail.com | AA8: Yes | AB8: 23625030001500 | AC8: https://drive.google.com/open?id=1p7jWoaNGA48ZsmXz8piawFvDD6h8MZPo | AD8: 36ACHFA3021A1Z7 | AE8: https://drive.google.com/open?id=1hZ4_XJa0ar_5viyQyWSwjO63ut7o3QIh | AF8: AWNPV9668G | AG8: https://drive.google.com/open?id=11LbxcMTLS62PuKE6EHwzu8WdUemKU5ba | AK8: https://drive.google.com/open?id=1LV1wXeDgKShlIJHBUn--Sn9J2gR1xgxD | AL8: 803705000004 | AM8: ICIC0008037 | AN8: ICICI BANK | AO8: VENKAT LINGAM | AP8: 8989873636 | AQ8: BOWLRISE.SRNAGAR@GMAIL.COM | AR8: AARAV SUNRISE HOSPITALITES | AS8: Yes | AT8: They got impress with our application take away point | AU8: No | AV8: Document Collection | AX8: 46056 | AY8: 0.23958333 | AZ8: parthive.maganti@capsdelivery.com | BR8: =Concatenate(BQ8,BP8,BO8,E8,T8) -> Sunrise Business Hotel
A9: 46057.408 | B9: 46056 | C9: 0.75 | D9: Intro Meeting | E9: ZYROS BIRYANI HOUSE | F9: 8 | G9: 300 | H9: YES | I9: 60000 | J9: Tier-2 (AOV <400) | K9: Swiggy, Zomato | L9: 22 | M9: 18 | N9: 1 | O9: Prop | P9: Yes | Q9: Active | R9: Not Applied | S9: https://www.google.com/maps/place/17%C2%B027'04.3%22N+78%C2%B023'30.1%22E/@17.4512028,78.389128,17z/data=!3m1!4b1!4m4!3m3!8m2!3d17.4512028!4d78.3917029?hl=en&entry=ttu&g_ep=EgoyMDI2MDIwMS4wIKXMDSoKLDEwMDc5MjA2OUgBUAM%3D | U9: NATVA SANTOSH KUMAR | V9: 6302181276 | W9: nsantosh086@gmail.com | X9: NA | AA9: Yes | AB9: 13625010001295 | AC9: https://drive.google.com/open?id=19PGovlvYadreb67eUHeNKzrktgJO-8bX | AD9: 36BQBPK2933A1ZD | AE9: https://drive.google.com/open?id=1xkvSfuIbWsf_ar7Z_3_MFx49cCnJTGSd | AJ9: https://drive.google.com/open?id=1zs5LVtkzfw6Ig4tlx1lPWSn0Lm-7bwoP | AK9: https://drive.google.com/open?id=12sEwp13vy0B0IOgjOaR48di8G3M0dgC6 | AL9: 6450935473 | AM9: KKBK0000561 | AO9: NATVA SANTOSH KUMAR | AP9: 6302181276 | AQ9: nsantosh086@gmail.com | AR9: NATVA SANTOSH KUMAR | AS9: Yes | AT9: ONBOARDED | AU9: No | AZ9: moin.khan@capsdelivery.com | BR9: =Concatenate(BQ9,BP9,BO9,E9,T9) -> ZYROS BIRYANI HOUSE
A10: 46057.417 | B10: 46055 | C10: 0.125 | D10: Intro Meeting | E10: Slice of Spice | F10: 150 | G10: 5000 | H10: own software | I10: 120000 | J10: Tier-1(AOV>400) | K10: None | N10: 15 | O10: Partnership | P10: Yes | Q10: Active | R10: Yes | S10: 2-52/1/3, Hitech City Rd, Phase 2, Kavuri Hills, Madhapur, Hyderabad, Telangana 500081 | U10: Venkat Lingam | V10: 888655996 | W10: bowlrise.srnagar@gmail.com | AA10: Yes | AB10: 23625032003555 | AC10: https://drive.google.com/open?id=1O-A-ESorVgS21JbM9bD4LsPgYXHMCp0d | AD10: 36AAKFE8997J1ZI | AE10: https://drive.google.com/open?id=15R5f8q3so1Ik7UrWJk_3rCjAQY8sBEFO | AF10: AAKFE8997J | AG10: https://drive.google.com/open?id=1r4LwvkbszhmmgLl56dsxPyTtENCSry3W | AJ10: https://drive.google.com/open?id=1kddVXBDtmyxBYZuEGyQzheu06kPD2YCr | AK10: https://drive.google.com/open?id=1HMbFf9NKxwpNmJpRUAoeT4JSbWFH_gsM | AL10: 112005003328 | AM10: ICIC0001120 | AN10: EASTIN HOTELS AND RESORTS | AO10: VAMSI | AP10: 9014707850 | AQ10: info@eastinhotel.com | AS10: Yes | AT10: Onboarded | AU10: No | AZ10: nitya.akshara@capsdelivery.com | BR10: =Concatenate(BQ10,BP10,BO10,E10,T10) -> Slice of Spice
A11: 46057.975 | B11: 46057 | C11: 0.91111111 | D11: Intro Meeting | E11: ROLO BAKERS | F11: 20 | G11: 250 | H11: PET POOJA | I11: 25000 | J11: Tier-2 (AOV <400) | K11: Swiggy, Zomato | L11: 15 | M11: 18 | N11: 1 | O11: Partnership | P11: Yes | Q11: Active | R11: No | S11: google.com/maps?q=17.440473,78.3934188&z=17&hl=en | U11: GM RAGHAVENDRA | V11: 9963968917 | W11: NA | AA11: Yes | AB11: 23624032003815 | AC11: https://drive.google.com/open?id=16IQXYD4HTTgs7GCdBU6iPTmSXHfWlbQY | AD11: 36ABJFR8448R1Z2 | AE11: https://drive.google.com/open?id=1QyRpGDX2lP1lX3GoLj4kqxGuQ7cNxZ5q | AF11: ABJFR8448R | AG11: https://drive.google.com/open?id=1wLa_Pt-AJbdtSV0NDD93Cgm0a-yocPNO | AO11: GM RAGHAVENDRA | AP11: 9963968917 | AR11: ROLO ONE BAKERS | AS11: Yes | AT11: ONBOARDED | AU11: No | AZ11: moin.khan@capsdelivery.com | BR11: =Concatenate(BQ11,BP11,BO11,E11,T11) -> ROLO BAKERS
A12: 46057.988 | B12: 46057 | C12: 0.93333333 | D12: Intro Meeting | E12: rayalseema spice restaurant | F12: 40 | G12: 300 | H12: PET POOJA | I12: 21000 | J12: Tier-2 (AOV <400) | K12: Swiggy, Zomato | L12: 20 | M12: 18 | N12: 1 | O12: Prop | P12: Yes | Q12: Active | R12: No | S12: https://www.google.com/maps/place/Rayalaseema+Spice+Restaurant/@17.4463018,78.3898889,17z/data=!3m1!4b1!4m6!3m5!1s0x3bcb91140c324827:0xb8961b47ea2ebc6a!8m2!3d17.4463018!4d78.3924638!16s%2Fg%2F11ks1mwcz0?entry=ttu&g_ep=EgoyMDI2MDIwMS4wIKXMDSoKLDEwMDc5MjA2OUgBUAM%3D | U12: narapu reddy | V12: 6301782448 | W12: rayalseemaspice@gmail.com | AA12: Yes | AB12: 13623013001342 | AC12: https://drive.google.com/open?id=12A0pBqsWeMNRgfr4-RewydCYL1MhGFzW | AD12: 36BDMPC6430Q1Z4 | AE12: https://drive.google.com/open?id=1w2-0S2iGSW_hsqhFAKZANxRRUo2t8rGA | AF12: BDMPC6430Q | AG12: https://drive.google.com/open?id=1pP1p8yHifkOvlMj3fFQXJ-_zZU02HhTR | AK12: https://drive.google.com/open?id=1B_C4vy9xoX9tPLwjSW2tR-EM6ekXOlYl | AL12: 20100061259823 | AM12: BDBL0002722 | AN12: BANDHAN BANK | AO12: POKURI PRATHYUSHA | AP12: 6301782448 | AR12: POKURI PRATHYUSHA | AS12: Yes | AT12: ONBOARDED | AU12: No | AZ12: moin.khan@capsdelivery.com | BR12: =Concatenate(BQ12,BP12,BO12,E12,T12) -> rayalseema spice restaurant
A13: 46057.997 | B13: 46057 | C13: 0.94722222 | D13: Intro Meeting | E13: alankrutha multicuisine restaurant | F13: 20 | G13: 300 | H13: PETPOOJA | I13: 24000 | J13: Tier-2 (AOV <400) | K13: Swiggy, Zomato | L13: 20 | M13: 18 | N13: 1 | O13: Prop | P13: No | Q13: Active | R13: No | S13: https://www.google.com/maps/place/Alankrutha+Restaurant/@17.44665,78.3922746,3a,75y,90t/data=!3m8!1e2!3m6!1sAF1QipN-ydSRKlr93jgWDRaakYdE5oV8xhAkUs2hDWna!2e10!3e12!6shttps:%2F%2Flh3.googleusercontent.com%2Fp%2FAF1QipN-ydSRKlr93jgWDRaakYdE5oV8xhAkUs2hDWna%3Dw203-h114-k-no!7i1920!8i1080!4m7!3m6!1s0x3bcb9100076d4f83:0x7e07d0c42ed99066!8m2!3d17.4466622!4d78.3923727!10e5!16s%2Fg%2F11m6k7vc6z?entry=ttu&g_ep=EgoyMDI2MDIwMS4wIKXMDSoKLDEwMDc5MjA2OUgBUAM%3D | U13: AKASH | V13: 8341514984 | W13: cakash121@gmail.com | AA13: Yes | AB13: 23625028001267 | AC13: https://drive.google.com/open?id=1yUrIaR5y55zD2nSA-kJ0RTpJklMZhyOE | AD13: na | AF13: AOXPC9349D | AG13: https://drive.google.com/open?id=1lHnQS6jFD0j-ODzzm6ncc6Fds_MkMTOj | AK13: https://drive.google.com/open?id=1xJurv609CUKpePCGd0rcMOwYy6MJKEto | AL13: 6598200001283 | AM13: BARB0DBMDHP | AN13: BANK OF BARODA | AO13: ALANKRUTHA RESTAURANT | AP13: 8341514984 | AQ13: cakash121@gmail.com | AR13: ALANKRUTHA MULTICUSINE RESTAURANT | AS13: Yes | AT13: ONBOARDED | AU13: No | AZ13: moin.khan@capsdelivery.com | BR13: =Concatenate(BQ13,BP13,BO13,E13,T13) -> alankrutha multicuisine restaurant
A14: 46058.414 | B14: 46057 | C14: 0.625 | D14: Intro Meeting | E14: GUNTUR MESS | F14: 20 | G14: 200 | H14: NA | I14: 10000 | J14: Tier-3 ( AOV<200 ) | K14: Zomato | N14: 1 | O14: Prop | P14: No | Q14: Active | R14: Yes | S14: YES | U14: SHIVA | V14: 9391167117 | W14: shiva@gmail.com | AA14: Yes | AS14: Yes | AT14: on boarded waiting for documents | AU14: No | AV14: Document Collection | AZ14: chanakya.inugala@capsdelivery.com | BR14: =Concatenate(BQ14,BP14,BO14,E14,T14) -> GUNTUR MESS
A15: 46058.833 | B15: 46058 | C15: 0.625 | D15: Intro Meeting | E15: Bihar Dhaba | F15: 30 | G15: 200 | H15: NA | I15: 15000 | J15: Tier-3 ( AOV<200 ) | K15: Swiggy, Zomato | L15: 22 | M15: 22 | N15: 1 | O15: Prop | P15: Yes | Q15: Active | R15: Yes | S15: yes | U15: prajwah kumar | V15: 9441674841 | W15: na | AA15: No | AT15: onboarded waiting for documets | AU15: No | AV15: Document Collection | AX15: 46059 | AY15: 0.625 | AZ15: chanakya.inugala@capsdelivery.com | BR15: =Concatenate(BQ15,BP15,BO15,E15,T15) -> Bihar Dhaba
A16: 46058.837 | B16: 46058 | C16: 0.81180556 | D16: Intro Meeting | E16: hunan chinese cusine | F16: 20 | G16: 200 | H16: NO POS | I16: 12000 | J16: Tier-2 (AOV <400) | K16: Swiggy, Zomato | L16: 18 | M16: 20 | N16: 1 | O16: Prop | P16: No | Q16: Active | R16: No | S16: https://www.google.com/maps/place/Hunan+Chinese+Cuisine/@17.4478451,78.3885023,17z/data=!3m1!4b1!4m6!3m5!1s0x3bcb91b50352f21f:0xee872dfeab40a154!8m2!3d17.4478451!4d78.3885023!16s%2Fg%2F11vxjzpgh9?hl=en&entry=ttu&g_ep=EgoyMDI2MDIwMS4wIKXMDSoKLDEwMDc5MjA2OUgBUAM%3D | U16: RAVI | V16: 7396735758 | W16: thehumanspice@gmail.com | X16: NA | Z16: NA | AA16: Yes | AB16: 23625032004054 | AC16: https://drive.google.com/open?id=1eq2DvTRrEKjx7F39onOqBAWekTlxGmlf | AD16: NA | AK16: https://drive.google.com/open?id=1EM4vsraBCi3CmJzJUZ8gpuR8XRGBOcDh | AL16: 1548257253 | AN16: HUNAN CHINESE CUSINE | AO16: RAVI | AP16: 7396735758 | AQ16: thehumanspice@gmail.com | AR16: Ravi | AS16: Yes | AT16: onboarded | AU16: No | AZ16: moin.khan@capsdelivery.com | BR16: =Concatenate(BQ16,BP16,BO16,E16,T16) -> hunan chinese cusine
A17: 46059.177 | B17: 46058 | C17: 0.73263889 | D17: Growth Meeting | T17: Krishna teeram | U17: Suresh | V17: 9985609966 | W17: krishnateeram2025@gmail.com | AA17: No | AT17: Onboarding done but Adhar and pan details didnt recevied at. | AU17: No | AV17: Need to receive some of the documents | AZ17: greeshma.vanneldas@capsdelivery.com | BR17: =Concatenate(BQ17,BP17,BO17,E17,T17) -> Krishna teeram
A18: 46059.179 | B18: 46058 | C18: 0.625 | D18: Growth Meeting | T18: Ahaladha kitchen | U18: Naveen | V18: 8555086883 | W18: didnt recevied | AA18: No | AT18: Onboarding done | AU18: No | AV18: Onboarding done. | AZ18: greeshma.vanneldas@capsdelivery.com | BR18: =Concatenate(BQ18,BP18,BO18,E18,T18) -> Ahaladha kitchen
A19: 46059.184 | B19: 46058 | C19: 0.79166667 | D19: Intro Meeting | E19: Rameshwaram cafe | F19: 80 | G19: 1 | H19: intro meeting not done | I19: 1 | J19: Tier-2 (AOV <400) | K19: Swiggy, Zomato | N19: 1 | O19: Intro meet not done because owner will be available after 19:00pm | P19: Yes | Q19: Active | R19: Not Applied | S19: 72, Capital Pk Rd, beside Jain Sadguru Capital Park, Cyber Hills Colony, VIP Hills, Silicon Valley, Madhapur, Serilingampalle (M), Hyderabad, Telangana 500081 | U19: no details | V19: no details | W19: no details | AA19: No | AU19: Yes | AV19: Met the front office team, | AZ19: greeshma.vanneldas@capsdelivery.com | BR19: =Concatenate(BQ19,BP19,BO19,E19,T19) -> Rameshwaram cafe
A20: 46059.334 | B20: 46058 | C20: 0.66666667 | D20: Intro Meeting | E20: Hamara Adda | F20: 30 | G20: 1 | H20: 1 | I20: 1 | J20: Tier-1(AOV>400) | K20: Swiggy, Zomato | N20: 1 | O20: Didnt meet the client,got the niumber of the owner | P20: Yes | Q20: Active | R20: Not Applied | S20: G-02, Ground Floor, Silicon Towers, Image Gardens Road, Madhapur, Hyderabad | U20: owner | V20: 8712220229 | W20: didnt received | AA20: No | AU20: Yes | AV20: To explain about our platform | AZ20: greeshma.vanneldas@capsdelivery.com | BR20: =Concatenate(BQ20,BP20,BO20,E20,T20) -> Hamara Adda
A21: 46059.336 | B21: 46058 | C21: 0.54166667 | D21: Follow up | T21: Delicia | U21: Vishwa | V21: 8522886035 | W21: didnt provided | AA21: No | AU21: Yes | AV21: Manager need to discuss with owner and he will get up to us,but I will follow up. | AZ21: greeshma.vanneldas@capsdelivery.com | BR21: =Concatenate(BQ21,BP21,BO21,E21,T21) -> Delicia
A22: 46059.34 | B22: 46058 | C22: 0.5 | D22: Follow up | T22: Palapitta Ruchulu | U22: didnt mention | V22: 7032682089 | W22: didnt got mail | AA22: No | AU22: Yes | AV22: Owner was busy during lunch and he said to follow up on monday | AZ22: greeshma.vanneldas@capsdelivery.com | BR22: =Concatenate(BQ22,BP22,BO22,E22,T22) -> Palapitta Ruchulu
A23: 46059.386 | B23: 46058 | C23: 0.75 | D23: Follow up | T23: lucky restaurant | U23: khasim | V23: 9849108337 | W23: na | AA23: No | AU23: Yes | AV23: Meeting with different POC | AX23: 46059 | AY23: 0.625 | AZ23: moin.khan@capsdelivery.com | BR23: =Concatenate(BQ23,BP23,BO23,E23,T23) -> lucky restaurant
A24: 46059.39 | B24: 46058 | C24: 0.66666667 | D24: Intro Meeting | E24: kiss me mandi | F24: 50 | G24: 300 | H24: na | I24: 15000 | J24: Tier-3 ( AOV<200 ) | K24: Swiggy | L24: 22 | M24: 20 | N24: 3 | O24: Prop | P24: Yes | Q24: Active | R24: Yes | S24: yes | U24: syed Aman | V24: 9866174396 | W24: NA | AA24: No | AU24: Yes | AV24: Contract Signing | AW24: NA | AX24: 46059 | AY24: 0.58333333 | AZ24: chanakya.inugala@capsdelivery.com | BR24: =Concatenate(BQ24,BP24,BO24,E24,T24) -> kiss me mandi
A25: 46059.394 | B25: 46058 | C25: 0.625 | D25: Intro Meeting | E25: Girl Friend Mandi | F25: 40 | G25: 300 | H25: na | I25: 30000 | J25: Tier-3 ( AOV<200 ) | K25: Swiggy, Zomato | L25: 22 | M25: 20 | N25: 2 | O25: Prop | P25: Yes | Q25: Active | R25: Yes | S25: NA | U25: shiek Nazeer | V25: 8886904546 | W25: na | AA25: No | AU25: Yes | AV25: Contract Signing | AX25: 46062 | AY25: 0.54166667 | AZ25: chanakya.inugala@capsdelivery.com | BR25: =Concatenate(BQ25,BP25,BO25,E25,T25) -> Girl Friend Mandi
A26: 46059.394 | B26: 46057 | C26: 0.50902778 | D26: Intro Meeting | E26: Shree Balaji Tiffin Center | F26: 60 | G26: 90 | H26: Mobile Software | I26: 16000 | J26: Tier-3 ( AOV<200 ) | K26: Swiggy, Zomato | L26: 22 | M26: 22 | N26: 1 | O26: Prop | P26: No | Q26: Active | R26: No | S26: https://maps.app.goo.gl/7YMoNqTWQYbg4jmu7 | U26: B.Raja Yeshwanth Kumar | V26: 9705812524 | W26: NA | AA26: Yes | AB26: 23625034003143 | AC26: https://drive.google.com/open?id=1FDLfrP2vE0w4X7UHEaSFNcpu27KdfG4j | AF26: AIOPB0243L | AG26: https://drive.google.com/open?id=1-S0Ms1yARTteTRwzAtfYIosgIvtAoKrD | AO26: B RAJA YESHWANTH KUMAR | AP26: 9705812524 | AR26: SHREE BALAJI TIFFIN CENTER | AS26: Yes | AT26: Onboarding is Done | AU26: No | AV26: NA | AZ26: ankitha.baske@capsdelivery.com | BR26: =Concatenate(BQ26,BP26,BO26,E26,T26) -> Shree Balaji Tiffin Center
A27: 46059.397 | B27: 46058 | C27: 0.625 | D27: Intro Meeting | E27: President Dhaba | F27: 50 | G27: 250 | H27: Nikhil | I27: 15000 | J27: Tier-2 (AOV <400) | K27: Swiggy, Zomato | L27: 22 | M27: 22 | N27: 2 | O27: Prop | P27: Yes | Q27: Active | R27: Yes | S27: yes | U27: Nikhil | V27: 7799956667 | W27: na | AA27: No | AU27: Yes | AV27: Meeting with different POC | AX27: 46062 | AY27: 0.625 | AZ27: chanakya.inugala@capsdelivery.com | BR27: =Concatenate(BQ27,BP27,BO27,E27,T27) -> President Dhaba
A28: 46059.397 | B28: 46058 | C28: 0.75 | D28: Intro Meeting | E28: lucky multicusine restaurant | F28: 200 | G28: 300 | H28: pet pooja | I28: 90000 | J28: Tier-2 (AOV <400) | K28: Swiggy, Zomato | L28: 15 | M28: 15 | N28: 1 | O28: Prop | P28: Yes | Q28: Active | R28: No | S28: https://www.google.com/maps/place/lucky+multi+cuisine+restaurant+madhapur/data=!4m2!3m1!1s0x3bcb915eea8173fb:0x9c806787d3a94d48?sa=X&ved=1t:242&ictx=111 | U28: Mansoor | V28: 9676213874 | W28: ya6822534@gmail.com | AA28: Yes | AB28: 13622013001491 | AC28: https://drive.google.com/open?id=1M7jn0BGrwdxzFH55n7AA8m6MyWVZRx1z | AD28: 36AAJFL6331Q1ZQ | AE28: https://drive.google.com/open?id=19lSB9R9cl_cCitMQsEsLggwyE9tp94F1 | AF28: AAJFL6331Q | AG28: https://drive.google.com/open?id=1NsZ5WcHnZIPbzaY8z4g91aZM_fe2ibN8 | AL28: 50200064899781 | AM28: HDFC0004277 | AN28: LUCKY MULTI CUISINE RESTAURANT | AO28: MANSOOR | AP28: 9676213874 | AQ28: ya6822534@gmail.com | AR28: LUCKY MULTI CUISINE RESTAURANT | AS28: Yes | AT28: ONBOARDED | AU28: No | AZ28: moin.khan@capsdelivery.com | BR28: =Concatenate(BQ28,BP28,BO28,E28,T28) -> lucky multicusine restaurant
A29: 46059.4 | B29: 46058 | C29: 0.75 | D29: Follow up | T29: godavari restaurant | U29: satya | V29: 9553119997 | W29: na | AA29: No | AU29: Yes | AV29: Meeting with different POC | AX29: 46059 | AY29: 0.54166667 | AZ29: moin.khan@capsdelivery.com | BR29: =Concatenate(BQ29,BP29,BO29,E29,T29) -> godavari restaurant
A30: 46059.401 | B30: 46058 | C30: 0.75 | D30: Follow up | T30: frozen bottles | U30: bhanu | V30: 8309230685 | W30: na | AA30: No | AU30: Yes | AV30: Meeting with different POC | AW30: interface about the AAP | AX30: 46059 | AY30: 0.58333333 | AZ30: moin.khan@capsdelivery.com | BR30: =Concatenate(BQ30,BP30,BO30,E30,T30) -> frozen bottles
A31: 46059.402 | B31: 46058 | C31: 0.66666667 | D31: Intro Meeting | E31: Adhirath | F31: 25 | G31: 200 | H31: na | I31: 20000 | J31: Tier-2 (AOV <400) | K31: Zomato | N31: 1 | O31: Prop | P31: Yes | Q31: Active | R31: Yes | S31: na | U31: Mukesh | V31: na | W31: na | AA31: No | AU31: Yes | AV31: Meeting with different POC | AX31: 46063 | AY31: 0.66666667 | AZ31: chanakya.inugala@capsdelivery.com | BR31: =Concatenate(BQ31,BP31,BO31,E31,T31) -> Adhirath
A32: 46059.403 | B32: 46058 | C32: 0.75 | D32: Follow up | T32: minyu | U32: ajay | V32: 7799223445 | W32: na | AA32: No | AU32: Yes | AV32: Meeting with different POC | AX32: 46059 | AY32: 0.625 | AZ32: moin.khan@capsdelivery.com | BR32: =Concatenate(BQ32,BP32,BO32,E32,T32) -> minyu
A33: 46059.404 | B33: 46058 | C33: 0.75 | D33: Follow up | T33: hyderabad host | U33: HARI | V33: 9849991664 | W33: NA | AA33: No | AU33: Yes | AV33: Meeting with different POC | AX33: 46059 | AY33: 0.625 | AZ33: moin.khan@capsdelivery.com | BR33: =Concatenate(BQ33,BP33,BO33,E33,T33) -> hyderabad host
A34: 46059.405 | B34: 46056 | C34: 0.68888889 | D34: Intro Meeting | E34: BIRYANI N BIRYANI | F34: 150 | G34: 150 | H34: NA | I34: 12000 | J34: Tier-3 ( AOV<200 ) | K34: Swiggy, Zomato | L34: 22 | M34: 22 | N34: 1 | O34: Partnership | P34: No | Q34: Active | R34: No | S34: https://maps.app.goo.gl/bVjfB92p6JmtmXyu9 | U34: Uttam Kumar | V34: 9010022093 | W34: NA | AA34: Yes | AB34: 23625030002129 | AC34: https://drive.google.com/open?id=1uEv1SbghR4V6SRNuV_W5cWmXTxOGaOTk | AO34: Uttam Kumar | AP34: 9010022093 | AR34: BIRYANI N BIRYANI | AS34: Yes | AU34: Yes | AV34: Document Collection | AZ34: ankitha.baske@capsdelivery.com | BR34: =Concatenate(BQ34,BP34,BO34,E34,T34) -> BIRYANI N BIRYANI
A35: 46059.406 | B35: 46058 | C35: 0.625 | D35: Intro Meeting | E35: Mehfil | F35: 70 | G35: 300 | H35: na | I35: 200000 | J35: Tier-2 (AOV <400) | K35: Swiggy, Zomato | L35: 22 | M35: 19 | N35: 10 | O35: Prop | P35: Yes | Q35: Active | R35: Yes | S35: yes | U35: Masood | V35: na | W35: na | AA35: No | AU35: Yes | AV35: Meeting with different POC | AW35: na | AX35: 46062 | AY35: 0.5 | AZ35: chanakya.inugala@capsdelivery.com | BR35: =Concatenate(BQ35,BP35,BO35,E35,T35) -> Mehfil
A36: 46059.406 | B36: 46058 | C36: 0.83333333 | D36: Follow up | T36: king mandi | U36: kavi raj | V36: 9059787788 | W36: NA | AA36: No | AU36: Yes | AV36: Meeting with different POC | AX36: 46059 | AY36: 0.79166667 | AZ36: moin.khan@capsdelivery.com | BR36: =Concatenate(BQ36,BP36,BO36,E36,T36) -> king mandi
A37: 46059.412 | B37: 46056 | C37: 0.54166667 | D37: Intro Meeting | E37: AL RAWAF HOME MADE DISHES | F37: 1 | G37: 300 | H37: Mobile Application | I37: 10000 | J37: Cloud Kitchen | K37: Swiggy | L37: 22 | M37: 22 | N37: 1 | O37: Prop | P37: No | Q37: Active | R37: No | S37: https://maps.app.goo.gl/3NoTX3DyLcp6bSMX7 | U37: ASFIYA SULTANA | V37: 9502632532 | W37: NA | AA37: Yes | AB37: 23625030004336 | AC37: https://drive.google.com/open?id=1jlS2uzGgdXIiBFtKTniOqZcQQP1Def9B | AF37: QGEPS7989L | AG37: https://drive.google.com/open?id=14vl9WR1NycmF9z9tVJiiS1sjEI4BpUgn | AS37: Yes | AT37: Onboarding Completed | AU37: No | AZ37: ankitha.baske@capsdelivery.com | BR37: =Concatenate(BQ37,BP37,BO37,E37,T37) -> AL RAWAF HOME MADE DISHES
A38: 46059.424 | B38: 46057 | C38: 0.57361111 | D38: Intro Meeting | E38: Govinda's Resturant | F38: 25 | G38: 400 | H38: Peta Puja | I38: 10000 | J38: Tier-2 (AOV <400) | K38: Swiggy, Zomato | L38: 21 | M38: 21 | N38: 2 | O38: Trust | P38: No | Q38: Active | R38: No | S38: https://maps.app.goo.gl/2zVYUFdRf5UbswRq8 | U38: Harish Dhas | V38: 9964818700 | W38: NA | AA38: Yes | AB38: 13622015000429 | AC38: https://drive.google.com/open?id=1XHti40Q6rcjbNTd4338mnP-gp5zYiTTo | AD38: 36AAAT10017P3ZM | AE38: https://drive.google.com/open?id=1wfQiIC4z7mrMJ5O4AxkRDuixJ2qPRhk2 | AF38: AAATI0017P | AG38: https://drive.google.com/open?id=1i3JNiPqA3bg9GskvIiKQOkcygNvWSwFo | AJ38: https://drive.google.com/open?id=1DMx_aqiNEP9UWnIpWFPjhq9IVflDo6wh | AK38: https://drive.google.com/open?id=1-_wWaTH5f5gEAIqiuRyYQXb_tpy1C51V | AO38: Harish Dhas | AP38: 9964818700 | AS38: Yes | AT38: Onboarding Completed | AU38: No | AZ38: ankitha.baske@capsdelivery.com | BR38: =Concatenate(BQ38,BP38,BO38,E38,T38) -> Govinda's Resturant
A39: 46059.426 | B39: 46175 | C39: 0.5625 | D39: Intro Meeting | E39: KNOX | F39: 200 | G39: 500 | H39: - | I39: 1 | J39: Tier-1(AOV>400) | K39: Swiggy, Zomato | L39: 22 | M39: 20 | N39: 1 | O39: Prop | P39: Yes | Q39: Active | R39: Yes | S39: NA | U39: Das | V39: 7842264138 | W39: - | AA39: No | AU39: Yes | AV39: Document Collection | AX39: 46059 | AY39: 0.5625 | AZ39: manasa.chigurupati@capsdelivery.com | BR39: =Concatenate(BQ39,BP39,BO39,E39,T39) -> KNOX
A40: 46059.43 | B40: 46055 | C40: 0.60416667 | D40: Intro Meeting | E40: NEW FARMAISH RESTAURANT | F40: 50 | G40: 300 | H40: NA | I40: 10000 | J40: Tier-3 ( AOV<200 ) | K40: Zomato | L40: 22 | M40: 22 | N40: 1 | O40: Prop | P40: No | Q40: Active | R40: No | S40: https://maps.app.goo.gl/Aiiv6UZV7TLfDBn47 | U40: SYED AMEER HUSSAIN | V40: 9742645678 | W40: NA | AA40: Yes | AB40: 23622028000187 | AC40: https://drive.google.com/open?id=1GwUWxdepNWvDVaZTDr0zsGPPIuKR_QoL | AD40: NA | AF40: BJVPS7089G | AG40: https://drive.google.com/open?id=1Uop_OL_J095nxx7Re4m3p62_DS8J7Cai | AO40: SYED | AP40: 9742645678 | AS40: Yes | AT40: Onboarding Completed | AU40: No | AZ40: ankitha.baske@capsdelivery.com | BR40: =Concatenate(BQ40,BP40,BO40,E40,T40) -> NEW FARMAISH RESTAURANT
A41: 46059.431 | B41: 46059 | C41: 0.47916667 | D41: Follow up | T41: Bahar Biryani | U41: Bodh | V41: 8978216439 | W41: NA | Z41: NA | AA41: No | AU41: Yes | AV41: Meeting with different POC | AW41: Comiision | AX41: 46059 | AY41: 0.47916667 | AZ41: akhila.narra@capsdelivery.com | BR41: =Concatenate(BQ41,BP41,BO41,E41,T41) -> Bahar Biryani
A42: 46059.431 | B42: 46059 | C42: 0.60416667 | D42: Intro Meeting | E42: Zythum | F42: 300 | G42: 1000 | H42: - | I42: 1 | J42: Tier-1(AOV>400) | K42: Swiggy, Zomato | L42: 22 | M42: 20 | N42: 1 | O42: Prop | P42: Yes | Q42: Active | R42: No | S42: - | U42: Bhargav | V42: 8019447999 | W42: - | AA42: No | AU42: Yes | AV42: Document Collection | AZ42: manasa.chigurupati@capsdelivery.com | BR42: =Concatenate(BQ42,BP42,BO42,E42,T42) -> Zythum
...

Sheet Follow ups

Sheet Detail19-Tier-1(AOV>400)
A1: Timestamp | B1: Date | C1: Time | D1: Type Of Meeting | E1: Restaurant Name Concat | F1: Seating Capacity | G1: AOV | H1: POS | I1: Daily Revenue? | J1: Kind of Restaurant | K1: Restaurant Live on | L1: Claimed Margins (Competition) | M1: Expected Margins (Caps) | N1: No.of Branches? | O1: Type of Ownership | P1: GST | Q1: FSSAI | R1: Labour License | S1: Google Map Business link | T1: Restaurant ID | U1: Name (POC-1) | V1: Contact Number (POC-1) | W1: Email- ID (POC-1) | X1: Name (POC-2) | Y1: Contact Number (POC-2) | Z1: Email- ID (POC-2) | AA1: Do you want to Submit Documents | AB1: FSSAI Number | AC1: FSSAI 2 | AD1: GST Number | AE1: GST 2 | AF1: PAN Number | AG1: PAN Card | AH1: Labour License Number | AI1: Labour License 2 | AJ1: Menu (Image) | AK1: Bank Account Proof | AL1: Account Number | AM1: IFSC | AN1: Name on Bank Account | AO1: Owner Name | AP1: Owner Contact Number | AQ1: Owner Email address | AR1: Legal Entity Name | AS1: Onboarding Done | AT1: Remarks(Comments) | AU1: Follow Up Meeting Required? | AV1: Meeting agenda for follow up | AW1: Points to be prepared | AX1: Meeting Date | AY1: Meeting Time | AZ1: Email address | BA1: Cold Walk/ Scheduled | BB1: POC Available | BC1: Manager Name | BD1: Manager Contact Details | BE1: Manager Email ID | BF1: Manager Contact Number | BG1: Manager Email ID 2 | BH1: Caps Magin % | BI1: Additional 2% Distance Margin | BJ1: Restaurant Open Time | BK1: Restaurant Close Time | BL1: Daily Online Orders | BM1: Restaurant Address | BN1: Cluster | BO1: Name of Restaurant Walk | BP1: Name of Restaurant | BQ1: Name of Ra
A2: 46059.334 | B2: 46058 | C2: 0.66666667 | D2: Intro Meeting | E2: Hamara Adda | F2: 30 | G2: 1 | H2: 1 | I2: 1 | J2: Tier-1(AOV>400) | K2: Swiggy, Zomato | N2: 1 | O2: Didnt meet the client,got the niumber of the owner | P2: Yes | Q2: Active | R2: Not Applied | S2: G-02, Ground Floor, Silicon Towers, Image Gardens Road, Madhapur, Hyderabad | U2: owner | V2: 8712220229 | W2: didnt received | AA2: No | AU2: Yes | AV2: To explain about our platform | AZ2: greeshma.vanneldas@capsdelivery.com
A3: 46059.426 | B3: 46175 | C3: 0.5625 | D3: Intro Meeting | E3: KNOX | F3: 200 | G3: 500 | H3: - | I3: 1 | J3: Tier-1(AOV>400) | K3: Swiggy, Zomato | L3: 22 | M3: 20 | N3: 1 | O3: Prop | P3: Yes | Q3: Active | R3: Yes | S3: NA | U3: Das | V3: 7842264138 | W3: - | AA3: No | AU3: Yes | AV3: Document Collection | AX3: 46059 | AY3: 0.5625 | AZ3: manasa.chigurupati@capsdelivery.com
A4: 46059.431 | B4: 46059 | C4: 0.60416667 | D4: Intro Meeting | E4: Zythum | F4: 300 | G4: 1000 | H4: - | I4: 1 | J4: Tier-1(AOV>400) | K4: Swiggy, Zomato | L4: 22 | M4: 20 | N4: 1 | O4: Prop | P4: Yes | Q4: Active | R4: No | S4: - | U4: Bhargav | V4: 8019447999 | W4: - | AA4: No | AU4: Yes | AV4: Document Collection | AZ4: manasa.chigurupati@capsdelivery.com
A5: 46059.542 | B5: 46059 | C5: 0.45486111 | D5: Intro Meeting | E5: Ohri's Cake Nation | F5: 150 | G5: 600 | H5: Brain power | I5: 15000 | J5: Tier-1(AOV>400) | K5: Swiggy, Zomato | L5: 17 | M5: 10 | N5: 11 | O5: Prop | P5: Yes | Q5: Active | R5: Yes | S5: na | U5: Ravi Kanth | V5: 6309794222 | W5: - | AA5: No | AU5: Yes | AV5: Document Collection | AW5: documents collection | AX5: 46069 | AY5: 0.45833333 | AZ5: manasa.chigurupati@capsdelivery.com
A6: 46059.586 | B6: 46059 | C6: 0.58333333 | D6: Intro Meeting | E6: KNOX | F6: 320 | G6: 450 | H6: pet pooja | I6: 20000 | J6: Tier-1(AOV>400) | K6: Swiggy, Zomato | L6: 20 | M6: 20 | N6: 1 | O6: Prop | P6: Yes | Q6: Active | R6: Yes | S6: - | U6: Jashwanth | V6: 9100007676 | W6: knowclubandkitchen@gmail.com | AA6: No | AU6: Yes | AV6: Document Collection | AW6: commissions & documents signs | AX6: 46064 | AY6: 0.39583333 | AZ6: manasa.chigurupati@capsdelivery.com
A7: 46059.667 | B7: 46059 | C7: 0.66666667 | D7: Intro Meeting | E7: Zythum | F7: 400 | G7: 500 | H7: explorates | I7: 100000 | J7: Tier-1(AOV>400) | K7: Swiggy, Zomato | L7: 20 | M7: 20 | N7: 1 | O7: PVT | P7: Yes | Q7: Active | R7: Yes | S7: - | U7: BHURDHABAN | V7: 8249132908 | W7: - | AA7: No | AU7: Yes | AV7: Negotiation | AW7: Commissions, documents collections, Competrtiors | AX7: 46063 | AY7: 0.70833333 | AZ7: manasa.chigurupati@capsdelivery.com
A8: 46063.526 | B8: 46063 | C8: 0.083333333 | D8: Intro Meeting | E8: Labond | F8: 150 | G8: 500 | H8: NA | I8: 23 | J8: Tier-1(AOV>400) | K8: Swiggy, Zomato | N8: 2 | O8: Partnership | P8: No | Q8: Active | R8: Yes | S8: NA | U8: Pasha | V8: 9032245891 | W8: na | AA8: No | AU8: Yes | AV8: Introduction | AW8: need to call him after 2 pm today | AX8: 46063 | AY8: 0.083333333 | AZ8: akhila.narra@capsdelivery.com | BA8: Cold Walk-in | BB8: Yes | BL8: NA | BN8: Jublii Hills
A9: 46063.528 | B9: 46063 | C9: 0.0625 | D9: Intro Meeting | E9: Chubby Chow | F9: 150 | G9: 500 | H9: na | I9: 23 | J9: Tier-1(AOV>400) | N9: 1 | O9: Prop | P9: Yes | Q9: Active | R9: Yes | S9: http | U9: Rajesh GM | V9: 6300797895 | W9: na | X9: na | AA9: No | AU9: Yes | AV9: Introduction | AW9: Intro meetng we Visted the Outelt Yesterday | AX9: 46064 | AY9: 0.52083333 | AZ9: akhila.narra@capsdelivery.com | BA9: Cold Walk-in | BB9: Yes | BL9: 25 | BN9: Jubliee hills
A10: 46063.602 | B10: 46063 | C10: 0.59722222 | D10: Intro Meeting | E10: Burma Burma | F10: 130 | G10: 1500 | H10: NA | J10: Tier-1(AOV>400) | K10: Swiggy, Zomato | N10: 1 | O10: NA | P10: No | Q10: Not Applied | R10: No | S10: NA | U10: Kajal | V10: 7977765789 | W10: NA | AA10: No | AU10: Yes | AV10: Introduction | AW10: We need to approach Marketing team | AZ10: ankitha.baske@capsdelivery.com | BA10: Cold Walk-in | BB10: Yes | BL10: 30-50
A11: 46063.687 | B11: 46063 | C11: 0.16666667 | D11: Intro Meeting | E11: president dhaba | F11: 250 | G11: 1000 | H11: na | J11: Tier-1(AOV>400) | K11: Swiggy, Zomato | L11: 18 | N11: 4 | O11: Prop | P11: Yes | Q11: Active | R11: Yes | S11: na | U11: vinod | V11: 7337001104 | W11: na | AA11: No | AU11: Yes | AV11: Introduction | AZ11: madhumitha.sonnakula@capsdelivery.com | BA11: Cold Walk-in | BB11: Yes | BN11: jubilee hills
A12: 46063.689 | B12: 46063 | C12: 0.1875 | D12: Intro Meeting | E12: my froyo land | F12: 25 | G12: 400 | H12: na | J12: Tier-1(AOV>400) | K12: Swiggy, Zomato | N12: 1 | O12: Prop | P12: Yes | Q12: Active | R12: Yes | S12: na | U12: kajal | V12: 9172541254 | W12: na | AA12: No | AU12: Yes | AV12: Introduction | AX12: 46064 | AY12: 0.5 | AZ12: madhumitha.sonnakula@capsdelivery.com | BA12: Cold Walk-in | BB12: Yes | BN12: jubilee hills
A13: 46063.707 | B13: 46063 | C13: 0.1875 | D13: Intro Meeting | E13: Rayalaseema Ruchulu | F13: 120 | G13: 600 | H13: Pet pooja | I13: 600000 | J13: Tier-1(AOV>400) | K13: Swiggy, Zomato, Magic Pin | L13: 15 | M13: 12 | N13: 4 | O13: Prop | P13: Yes | Q13: Active | R13: Yes | S13: - | U13: Rajini | V13: 9959020310 | W13: Info@rayalaseemaruchulu.com | AA13: No | AU13: Yes | AV13: Negotiation | AW13: Commisions | AZ13: manasa.chigurupati@capsdelivery.com | BA13: Scheduled | BN13: Hi tech city, lakdikapol, ameerpet, Jubilee hills
A14: 46063.713 | B14: 46063 | C14: 0.70833333 | D14: Intro Meeting | E14: Rayalaseema spice | F14: 80 | G14: 500 | H14: NA | J14: Tier-1(AOV>400) | K14: Swiggy, Zomato | N14: 1 | O14: NA | P14: No | Q14: Not Applied | R14: No | S14: NA | U14: Narsigin Rao | V14: 7075777491 | W14: NA | AA14: No | AU14: Yes | AV14: Introduction | AZ14: ankitha.baske@capsdelivery.com | BA14: Cold Walk-in | BB14: Yes
A15: 46063.716 | B15: 46063 | C15: 0.71388889 | D15: Intro Meeting | E15: Kake di hatti | F15: 120 | G15: 500 | H15: N/a | J15: Tier-1(AOV>400) | K15: Swiggy, Zomato | N15: 1 | O15: N/a | P15: Yes | Q15: Active | R15: No | S15: Na | U15: Prabhakar | V15: 9140523292 | W15: Na | AA15: No | AU15: Yes | AV15: Meeting with different POC | AW15: Owner will be available after 21:00Pm in the restaurant(Kondapur) | AZ15: greeshma.vanneldas@capsdelivery.com | BA15: Cold Walk-in | BB15: Yes
A16: 46063.727 | B16: 46063 | C16: 0.72569444 | D16: Intro Meeting | E16: Vaikuntapuram | F16: 60 | G16: 400 | H16: NA | J16: Tier-1(AOV>400) | K16: Swiggy, Zomato | N16: 1 | O16: NA | P16: Yes | Q16: Active | R16: Yes | S16: NA | U16: Venkatesh | V16: 9392857604 | W16: Na | AA16: No | AU16: Yes | AV16: Meeting with different POC | AW16: Manager will be available after 7 pm | AZ16: greeshma.vanneldas@capsdelivery.com | BA16: Cold Walk-in | BB16: Yes
A17: 46064.554 | B17: 46064 | C17: 0.54444444 | D17: Intro Meeting | E17: Namesthe | F17: 1 | G17: 500 | H17: NA | J17: Tier-1(AOV>400) | N17: 1 | O17: NA | P17: Yes | Q17: Active | R17: Yes | S17: NA | U17: Basawath | V17: 9052253253 | W17: Na | AA17: No | AU17: Yes | AV17: Meeting with different POC | AZ17: ankitha.baske@capsdelivery.com | BA17: Cold Walk-in | BB17: Yes
A18: 46064.909 | B18: 46053 | C18: 0.074305556 | D18: Intro Meeting | E18: fb bakers | F18: 10 | G18: 500 | H18: na | J18: Tier-1(AOV>400) | K18: Swiggy, Zomato | N18: 1 | O18: Prop | P18: Yes | Q18: Active | R18: Yes | S18: na | U18: ashok | V18: 8939369888 | W18: nA | AA18: No | AU18: Yes | AV18: Introduction | AZ18: madhumitha.sonnakula@capsdelivery.com | BA18: Cold Walk-in | BB18: Yes | BN18: mehandipatanam
A19: 46064.91 | B19: 46053 | C19: 0.10416667 | D19: Intro Meeting | E19: MAHARAJA | F19: 1 | G19: 600 | H19: NA | J19: Tier-1(AOV>400) | K19: Swiggy, Zomato | N19: 1 | O19: Prop | P19: Yes | Q19: Active | R19: Yes | S19: NA | U19: UMAR KHAN | V19: 9885199151 | W19: NA | AA19: No | AU19: Yes | AV19: Introduction | AZ19: madhumitha.sonnakula@capsdelivery.com | BA19: Cold Walk-in | BB19: Yes | BN19: MEHANDIPATANAM
A20: 46065.195 | B20: 46064 | C20: 0.66666667 | D20: Intro Meeting | E20: Aaha | F20: 50 | G20: 500 | H20: Na | I20: 50000 | J20: Tier-1(AOV>400) | K20: Swiggy, Zomato | L20: 22 | M20: 19 | N20: 2 | O20: Prop | P20: Yes | Q20: Active | R20: No | S20: Na | U20: Raju | V20: 8688995094 | W20: Na | AA20: No | AU20: Yes | AV20: Meeting with different POC | AX20: 46065 | AY20: 0.625 | AZ20: chanakya.inugala@capsdelivery.com | BA20: Cold Walk-in | BB20: Yes | BL20: 50 | BN20: Manikonda
A21: 46066.523 | B21: 46066 | C21: 0.52152778 | D21: Intro Meeting | E21: Patiala plate | F21: 60 | G21: 500 | H21: Na | J21: Tier-1(AOV>400) | K21: Swiggy, Zomato | N21: 1 | O21: Na | P21: Yes | Q21: Active | R21: Not Applied | S21: 5G Patiala Plate North Indian | U21: Jaffar | V21: 8319942382 | W21: Na | AA21: No | AU21: Yes | AV21: Introduction | AW21: Manager need to discuss with owner | AZ21: greeshma.vanneldas@capsdelivery.com | BA21: Cold Walk-in | BB21: Yes | BP21: Patiala plate
A22: 46066.561 | B22: 46066 | C22: 0.52083333 | D22: Intro Meeting | E22: The spicy venue | F22: 250 | G22: 500 | H22: Na | I22: 70000 | J22: Tier-1(AOV>400) | K22: Swiggy, Zomato | N22: 1 | O22: PVT | P22: Yes | Q22: Active | R22: Yes | S22: https://share.google/NGYbU0jsM5QQzbN2H | U22: Lead | V22: Lead | W22: Lead | AA22: No | AU22: Yes | AV22: Meeting with different POC | AZ22: parthive.maganti@capsdelivery.com | BA22: Scheduled | BN22: Na | BP22: The spicy venue
A23: 46066.563 | B23: 46066 | C23: 0.54166667 | D23: Intro Meeting | E23: Sri Kanya comfort | F23: 200 | G23: 500 | H23: Na | I23: 80000 | J23: Tier-1(AOV>400) | K23: Swiggy, Zomato | N23: 1 | O23: Prop | P23: Yes | Q23: Active | R23: No | S23: https://share.google/Rak1DxkX5m16fu3uV | U23: Lead murali | V23: Lead | W23: Lead | AA23: No | AU23: Yes | AV23: Negotiation | AZ23: parthive.maganti@capsdelivery.com | BA23: Scheduled | BL23: 100 | BP23: Sri Kanya comfort
A24: 46066.566 | B24: 46066 | C24: 0.54166667 | D24: Intro Meeting | E24: Itihaas Restaurant and Banquets | F24: 500 | G24: 500 | H24: Na | I24: 80000 | J24: Tier-1(AOV>400) | K24: Swiggy, Zomato | N24: 1 | O24: Partnership | P24: Yes | Q24: Active | R24: Yes | S24: https://share.google/CHy1tdi4IZ9qchmkI | U24: Lead murali | V24: Lead | W24: lead | AA24: No | AU24: Yes | AV24: Negotiation | AZ24: parthive.maganti@capsdelivery.com | BA24: Scheduled | BL24: 80 | BN24: Na | BP24: Itihaas Restaurant and Banquets
A25: 46066.569 | B25: 46066 | C25: 0.52083333 | D25: Intro Meeting | E25: Gumagumalu | F25: 150 | G25: 350 | H25: Na | J25: Tier-1(AOV>400) | K25: Swiggy, Zomato | N25: 1 | O25: Partnership | P25: Yes | Q25: Active | R25: Yes | S25: https://share.google/M0vWSrt6a1iawTVxb | U25: Lead | V25: Lead | W25: lead | X25: lead | AA25: No | AU25: Yes | AW25: Na | AX25: 46067 | AY25: 0.5 | AZ25: parthive.maganti@capsdelivery.com | BA25: Scheduled | BP25: Gumagumalu
A26: 46066.696 | B26: 46066 | C26: 0.10416667 | D26: Intro Meeting | E26: Kadali kitchen | F26: 90 | G26: 900 | H26: Pet poja | J26: Tier-1(AOV>400) | K26: Swiggy, Zomato | N26: 1 | O26: PVT | P26: Yes | Q26: Active | R26: No | S26: https://maps.google.com/maps/place//data=!4m2!3m1!1s0x3bcb974d964ebe25:0xece3580d587566f?entry=s&sa=X&ved=2ahUKEwjugt--qtaSAxV3TGwGHaIQFDYQ4kB6BAgXEAA&hl=en | U26: Rohan | V26: 9989649223 | W26: Ahsth | AA26: No | AU26: Yes | AV26: Meeting with different POC | AW26: 19++ | AX26: 46069 | AY26: 0.10416667 | AZ26: akhila.narra@capsdelivery.com | BA26: Scheduled | BN26: Jubliee Hills | BP26: Kadali kitchen
A27: 46066.706 | B27: 46066 | C27: 0.20138889 | D27: Intro Meeting | E27: Hyderabad wala | F27: 120 | G27: 500 | H27: Pet pooja | J27: Tier-1(AOV>400) | K27: Swiggy, Zomato | N27: 1 | O27: PVT, Prop | P27: Yes | Q27: Active | R27: Yes | S27: http | U27: Hyder | V27: 8886741212 | W27: Na | AA27: No | AU27: Yes | AV27: Meeting with different POC | AZ27: akhila.narra@capsdelivery.com | BA27: Scheduled | BN27: Banjara hills | BP27: Hyderabad wala
A28: 46069.806 | B28: 46069 | C28: 0.75 | D28: Intro Meeting | E28: Hard Rock CafeHard Rock Cafe | F28: 80 | G28: 800 | H28: Urban Piper | J28: Tier-1(AOV>400) | K28: Swiggy, Zomato | N28: 3 | O28: PVT | P28: Yes | Q28: Active | R28: Not Applied | S28: https://share.google/Dw0aunpNz3KYzSitm | T28: Hard Rock Cafe | U28: T Naveen Kumar | V28: 9985287122 | W28: om.hrchyd@jsmcorp.in | AA28: No | AT28: Asked to share the proposal over the email | AU28: Yes | AV28: Introduction | AX28: 46070 | AZ28: manisha.kumari@capsdelivery.com | BA28: Cold Walk-in | BB28: Yes | BP28: Hard Rock Cafe
A29: 46070.385 | B29: 46070 | C29: 0.27083333 | D29: Intro Meeting | E29: Tiffins and more | F29: 80 | G29: 900 | H29: Pet Pooja | J29: Tier-1(AOV>400) | K29: Swiggy, Zomato | N29: 1 | O29: Prop | P29: Yes | Q29: Active | R29: Yes | S29: http | U29: Arun | V29: 99855 59905 | W29: Na | AA29: No | AT29: Na | AU29: Yes | AV29: Meeting with different POC | AX29: 46072 | AY29: 0.10416667 | AZ29: akhila.narra@capsdelivery.com | BA29: Cold Walk-in | BB29: Yes | BN29: Jubliee Hills | BP29: Tiffins and more
A30: 46070.51 | B30: 46069 | C30: 0.54513889 | D30: Intro Meeting | E30: Cafe Delhi Heights | F30: 98 | G30: 600 | H30: Na | I30: 7200 | J30: Tier-1(AOV>400) | K30: Swiggy, Zomato, Magic Pin | N30: 52 | O30: PVT | P30: Yes | Q30: Active | R30: No | S30: https://www.google.com/maps?gs_lcrp=EgZjaHJvbWUqDQgBEC4YrwEYxwEYgAQyCggAEEUYFhgeGDkyDQgBEC4YrwEYxwEYgAQyBwgCEAAYgAQyBwgDEAAYgAQyBwgEEAAYgAQyCAgFEAAYFhgeMggIBhAAGBYYHjIICAcQABgWGB4yCAgIEAAYFhge0gEJMTc0OTdqMGo3qAIIsAIB8QVsLCl7Jib_JQ&um=1&ie=UTF-8&fb=1&gl=in&sa=X&geocode=KRnXhiy4kcs7MRTcZ3ygvDfN&daddr=Shop+No.+S-16,+Second+Floor,+Level+4,+Inorbit+Mall+Mindspace,+Cyberabad,+Madhapur,+Hyderabad,+Telangana+500081 | U30: Kishan Negi (Head Office POC) | V30: 9818808004 | W30: NA | X30: Rajan (Asst. Rest. Manager) | Y30: 9281054033 | Z30: NA | AA30: No | AT30: Call Mr. Kishan | AU30: Yes | AV30: Negotiation | AW30: Call Mr. Kishan | AX30: 46071 | AY30: 0.75 | AZ30: amit.kaler@capsdelivery.com | BA30: Cold Walk-in | BB30: Yes | BL30: 10 | BN30: Hi-tech city | BP30: Cafe Delhi Heights
A31: 46070.516 | B31: 46069 | C31: 0.54166667 | D31: Intro Meeting | E31: Chutnety's | F31: 150 | G31: 650 | H31: Na | I31: 500000 | J31: Tier-1(AOV>400) | K31: Swiggy, Zomato, Magic Pin | N31: 7 | O31: PVT | P31: Yes | Q31: Active | R31: No | S31: https://www.google.com/maps?sca_esv=d6eb6bac57f34326&sxsrf=ANbL-n4B5OSWpuRwcNbMRnTof1uYTLjeBg:1771311097540&biw=1470&bih=723&uact=5&gs_lp=Egxnd3Mtd2l6LXNlcnAiFWNodXRuZXlzIGlub3JiaXQgbWFsbDILEC4YgAQYxwEYrwEyBRAAGIAEMgYQABgHGB4yBBAAGB4yBBAAGB4yAhAmMgIQJjILEAAYgAQYhgMYigUyCxAAGIAEGIYDGIoFMgUQABjvBTIaEC4YgAQYxwEYrwEYlwUY3AQY3gQY4ATYAQFInwlQAFivB3AAeAGQAQCYAX6gAfgGqgEDMy41uAEDyAEA-AEBmAIGoALYBcICDRAuGIAEGMcBGA0YrwHCAgcQABiABBgNwgIcEC4YgAQYxwEYDRivARiXBRjcBBjeBBjgBNgBAZgDALoGBggBEAEYFJIHAzEuNaAHz0WyBwMxLjW4B9gFwgcFMi00LjLIByWACAA&um=1&ie=UTF-8&fb=1&gl=in&sa=X&geocode=KcOruzNYkcs7MWMzMvunEor6&daddr=Inorbit+Mall+Rd,+Mind+Space,+Vittal+Rao+Nagar,+HITEC+City,+Hyderabad,+Telangana+500081 | U31: Gaffar Khan | V31: 7893734731 | W31: Na | AA31: No | AT31: Call Mr. Gaffar and meet him at 5 pm at Jubliee Hills office | AU31: Yes | AV31: Introduction | AW31: Call and meet Mr. Gaffar | AX31: 46070 | AY31: 0.70833333 | AZ31: amit.kaler@capsdelivery.com | BA31: Cold Walk-in | BB31: Yes | BN31: Hi-Tech City | BP31: Chutnety's
A32: 46070.524 | B32: 46069 | C32: 0.58333333 | D32: Intro Meeting | E32: Foo | F32: 140 | G32: 1500 | H32: NA | I32: 1 | J32: Tier-1(AOV>400) | K32: Swiggy, Zomato | L32: 1 | N32: 2 | O32: PVT | P32: Yes | Q32: Active | R32: Yes | S32: https://www.google.com/maps?sca_esv=d6eb6bac57f34326&sxsrf=ANbL-n4yy65I9ZopH6s6emlSjdlh6FYi8g:1771311529307&biw=1470&bih=723&uact=5&gs_lp=Egxnd3Mtd2l6LXNlcnAiEGZvbyBpbm9yYml0IG1hbGwyCxAuGIAEGMcBGK8BMgUQABiABDIGEAAYBxgeMgYQABgHGB4yBhAAGAcYHjIEEAAYHjILEAAYgAQYhgMYigUyCxAAGIAEGIYDGIoFMgsQABiABBiGAxiKBTILEAAYgAQYhgMYigUyGhAuGIAEGMcBGK8BGJcFGNwEGN4EGOAE2AEBSMEFUABY2ANwAHgBkAEAmAGZAaABlgSqAQMwLjS4AQPIAQD4AQGYAgOgAqoDwgIKEAAYgAQYsQMYDcICExAuGIAEGLEDGMcBGA0YjgUYrwHCAgcQABiABBgNwgIQEC4YgAQYxwEYDRiOBRivAZgDAOIDBRIBMSBAugYGCAEQARgUkgcDMC4zoAeUOrIHAzAuM7gHqgPCBwUyLTIuMcgHEoAIAA&um=1&ie=UTF-8&fb=1&gl=in&sa=X&geocode=KUP5SZoUkcs7MTS3fLj-rgKR&daddr=Level+4,+Inorbit+Mall+Cyberabad,+APIIC+Software+Layout,+Madhapur,+Hyderabad,+Telangana+500081 | U32: Prajitesh (GM) | V32: 7030998709 | W32: NA | X32: Amitava (Entry Manager) | Y32: 9832874225 | AA32: No | AT32: Call Mr. Prajitesh | AU32: Yes | AV32: Introduction | AW32: Call Mr. Prajitesh | AX32: 46071 | AY32: 0.70833333 | AZ32: amit.kaler@capsdelivery.com | BA32: Cold Walk-in | BB32: Yes | BL32: NA | BN32: Hi-Tech City | BP32: Foo
A33: 46070.526 | B33: 46069 | C33: 0.58333333 | D33: Intro Meeting | E33: Popoyes | F33: 1 | G33: 400 | H33: POSBANK | I33: 120000 | J33: Tier-1(AOV>400) | K33: Swiggy, Zomato | N33: 5 | O33: PVT | P33: Yes | Q33: Active | R33: Yes | S33: https://www.google.com/maps?gs_lcrp=EgZjaHJvbWUyBggAEEUYOTIPCAEQLhgNGK8BGMcBGIAEMgkIAhAAGA0YgAQyCQgDEAAYDRiABDIJCAQQABgNGIAEMggIBRAAGBYYHjIICAYQABgWGB4yCAgHEAAYFhgeMggICBAAGBYYHtIBCDgwMDdqMGo0qAIAsAIA&um=1&ie=UTF-8&fb=1&gl=in&sa=X&geocode=KR1HXg5tkcs7MdTqStPsyZvd&daddr=64,+Inorbit+Mall+Rd,+APIIC+Software+Layout,+Madhapur,+Hyderabad,+Telangana+500081 | U33: Mahender (Area Manager) | V33: 9663743265 | W33: NA | X33: Raju Samba | AA33: No | AT33: Call Mr. Mahendra | AU33: Yes | AV33: Introduction | AW33: Call Mr. Mahendra | AX33: 46071 | AY33: 0.58333333 | AZ33: amit.kaler@capsdelivery.com | BA33: Cold Walk-in | BB33: Yes | BL33: 200 | BN33: Hi-Tech City | BP33: Popoyes
A34: 46070.534 | B34: 46069 | C34: 0.58333333 | D34: Intro Meeting | E34: California Burrito | F34: 1 | G34: 300 | H34: NA | I34: 90000 | J34: Tier-1(AOV>400) | K34: Swiggy, Zomato | N34: 33 | O34: PVT | P34: Yes | Q34: Active | R34: Yes | S34: https://www.google.com/maps?gs_lcrp=EgZjaHJvbWUqBwgBECEYoAEyBggAEEUYOTIHCAEQIRigATIHCAIQIRigATIHCAMQIRigATIHCAQQIRigATIHCAUQIRiPAjIHCAYQIRiPAtIBCTE0Mzk2ajBqNKgCALACAA&um=1&ie=UTF-8&fb=1&gl=in&sa=X&geocode=KY0d_WHukcs7Mdgo-dk7ysUX&daddr=L4,+Inorbit+Mall,+Inorbit+Mall+Rd,+Mind+Space,+Kavuri+Hills,+Madhapur,+Hyderabad,+Telangana+500081 | U34: Mr. Amar (Area Manager) | V34: 7002773847 | W34: NA | X34: Charanjit (Shift Manager) | AA34: No | AT34: No food deliveries on Inorbit location due to high demand and small kitchen need to approach for different locations | AU34: Yes | AV34: Introduction | AW34: Call Mr Amar | AX34: 46071 | AY34: 0.54166667 | AZ34: amit.kaler@capsdelivery.com | BA34: Cold Walk-in | BB34: Yes | BL34: 300 | BN34: Hi-Tech City | BP34: California Burrito
A35: 46070.537 | B35: 46069 | C35: 0.54166667 | D35: Intro Meeting | E35: KFC Inorbit Mall | F35: 1 | G35: 500 | H35: NA | I35: 1 | J35: Tier-1(AOV>400) | K35: Swiggy, Zomato | N35: 30 | O35: PVT | P35: Yes | Q35: Active | R35: Yes | S35: https://www.google.com/maps?gs_lcrp=EgZjaHJvbWUyBggAEEUYOTISCAEQLhgNGK8BGMcBGIAEGI4FMgkIAhAAGA0YgAQyCQgDEAAYDRiABDIJCAQQABgNGIAEMgkIBRAAGA0YgAQyCAgGEAAYFhgeMggIBxAAGBYYHjIICAgQABgWGB7SAQgzODUwajBqNKgCALACAA&um=1&ie=UTF-8&fb=1&gl=in&sa=X&geocode=KRmtG-nNk8s7MY6SesYBMWDP&daddr=64,+APIIC+Software+Layout,+Inorbit+Mall+F+%26+B+14B,+Hi+Tech+City,+Madhapur,+Hyderabad,+Telangana+500081 | U35: KSN Murthi (Delivery Manager) | V35: 9398596919 | W35: NA | X35: Ravi Teja (Area Manager) | Y35: 7416690785 | Z35: NA | AA35: No | AT35: KFC coming up with their own delivery app have own delivery partners and third party tie ups for peaks. Need to connect with delivery manager | AU35: Yes | AV35: Introduction | AW35: Call Mr. KSN Murhi | AX35: 46071 | AY35: 0.58333333 | AZ35: amit.kaler@capsdelivery.com | BA35: Cold Walk-in | BB35: Yes | BL35: 1 | BN35: Hi-Tech City | BP35: KFC Inorbit Mall
A36: 46070.542 | B36: 46069 | C36: 0.58333333 | D36: Intro Meeting | E36: Gabru Di Chaap | F36: 1 | G36: 600 | H36: Pet Pooja | I36: 24000 | J36: Tier-1(AOV>400) | K36: Swiggy, Zomato | N36: 9 | O36: PVT | P36: Yes | Q36: Active | R36: Yes | S36: https://www.google.com/maps?sca_esv=d6eb6bac57f34326&sxsrf=ANbL-n7BVT6m7RNWJrGmzVXHAzXMfEDB9w:1771313119547&biw=1470&bih=723&gs_lp=Egxnd3Mtd2l6LXNlcnAiEWdhYnJ1IGRpIGNoYWFwIEluKgIIADILEC4YgAQYxwEYrwEyCxAuGIAEGMcBGK8BMgUQABiABDIFEAAYgAQyBRAAGIAEMgsQLhiABBjHARivATIFEAAYgAQyBRAAGIAEMgYQABgWGB4yBhAAGBYYHjIaEC4YgAQYxwEYrwEYlwUY3AQY3gQY4ATYAQFIzUdQ9gFY-TtwAXgBkAEAmAGUAaABmQOqAQMwLjO4AQPIAQD4AQGYAgWgAtEOwgIKEAAYsAMY1gQYR8ICDRAAGLADGNYEGEcYyQPCAhAQABiABBiwAxiSAxhDGIoFwgIOEAAYgAQYsAMYkgMYigXCAg0QABiABBiwAxhDGIoFwgITEC4YgAQYsAMYQxjIAxiKBdgBAcICHBAuGIAEGLADGEMYxwEYyAMYigUYjgUYrwHYAQHCAhkQLhiABBiwAxjRAxhDGMcBGMgDGIoF2AEBwgIZEC4YgAQYsAMYQxjHARjIAxiKBRivAdgBAcICDhAAGLADGOQCGNYE2AEBwgIKEAAYgAQYQxiKBcICDRAAGIAEGEMYyQMYigXCAggQABiABBiSA8ICDhAuGIAEGMcBGI4FGK8BmAMAiAYBkAYTugYGCAEQARgIkgcHMS4zLjctMaAHkTGyBwMwLjO4B7MDwgcHMC4xLjMuMcgHF4AIAA&um=1&ie=UTF-8&fb=1&gl=in&sa=X&geocode=Kf__jy5Ykcs7MUbczbUEhGV-&daddr=Inorbit+mall,+Food+court,+Mindspace,+HUDA+Techno+Enclave,+HITEC+City,+Hyderabad,+Telangana+500081 | U36: Umar (Area Manager) (Generally Available at Sarascity Mall) | V36: 8374972864 | W36: NA | AA36: No | AT36: Call Mr. Umar | AU36: Yes | AV36: Introduction | AW36: Call Mr. Umar | AX36: 46071 | AY36: 0.58333333 | AZ36: amit.kaler@capsdelivery.com | BA36: Cold Walk-in | BB36: Yes | BL36: 40 | BN36: Hi-Tech City | BP36: Gabru Di Chaap
A37: 46070.549 | B37: 46069 | C37: 0.58333333 | D37: Intro Meeting | E37: AM AHA | F37: 130 | G37: 1200 | H37: NA | J37: Tier-1(AOV>400) | K37: Swiggy, Zomato | N37: 1 | O37: PVT | P37: Yes | Q37: Active | R37: Yes | S37: https://www.google.com/maps?sca_esv=d6eb6bac57f34326&sxsrf=ANbL-n6zMXS_xjfTwnoF_9GIZIWGUolzMg:1771313953825&biw=1470&bih=723&uact=5&gs_lp=Egxnd3Mtd2l6LXNlcnAiD2FtIGFoYSBpbiBvcmJpdDICECYyBRAAGO8FMgUQABjvBTIFEAAY7wUyCBAAGIAEGKIEMgUQABjvBUj7B1CvA1jEBnABeACQAQCYAaIBoAGiA6oBAzAuM7gBA8gBAPgBAZgCBKACtgPCAhAQLhiABBiwAxjHARgNGK8BwgIJEAAYsAMYDRgewgILEAAYsAMYBRgNGB7CAg0QABiwAxgFGAoYDRgewgILEAAYsAMYCBgNGB7CAgYQABgNGB6YAwCIBgGQBgeSBwMxLjOgB8QOsgcDMC4zuAexA8IHBTAuMS4zyAcMgAgA&um=1&ie=UTF-8&fb=1&gl=in&sa=X&geocode=KfVTvJL4kcs7MRjkfwJO-CAP&daddr=4th+Floor,+64,+Inorbit+Mall+Rd,+APIIC+Software+Layout,+Madhapur,+Hyderabad,+Telangana+500081 | U37: Mr. Laxman | V37: 7093369917 | W37: Na | X37: reference given by Miss Sandhya | AA37: No | AT37: Call Mr. Laxman | AU37: Yes | AV37: Introduction | AW37: Call Mr. Laxman | AX37: 46071 | AY37: 0.5 | AZ37: amit.kaler@capsdelivery.com | BA37: Cold Walk-in | BB37: Yes | BN37: Hi-Tech City | BP37: AM AHA
A38: 46070.552 | B38: 46069 | C38: 0.5 | D38: Intro Meeting | E38: Amnesia Sky Bar | F38: 700 | G38: 550 | H38: Breeza (Exporex) | J38: Tier-1(AOV>400) | K38: Swiggy, Zomato | N38: 1 | O38: PVT | P38: Yes | Q38: Active | R38: Yes | S38: https://www.google.com/maps?um=1&ie=UTF-8&fb=1&gl=in&sa=X&geocode=KUF8vUYlkcs7MS0rNCnlKQ5i&daddr=103,+104,+5th+Floor,+Inorbit+Mall,+Software+Units+Layout,+Madhapur,+Hyderabad,+Telangana+500081 | U38: Mr. Pasha | V38: 7731019977 | W38: NA | X38: Mr. Sahoo | Y38: 7731019988 | AA38: No | AT38: Meet after calling Mr. Pasha | AU38: Yes | AV38: Introduction | AW38: Meet Mr, Pasha post 4 pm on Wednesday | AX38: 46071 | AY38: 0.66666667 | AZ38: amit.kaler@capsdelivery.com | BA38: Cold Walk-in | BB38: Yes | BN38: Hi-Tech City | BP38: Amnesia Sky Bar
A39: 46070.556 | B39: 46069 | C39: 0.58333333 | D39: Intro Meeting | E39: Absolute Barbeque | F39: 150 | G39: 1200 | H39: In House | J39: Tier-1(AOV>400) | K39: Swiggy, Zomato | N39: 14 | O39: PVT | P39: Yes | Q39: Active | R39: Yes | S39: https://www.google.com/maps?sca_esv=d6eb6bac57f34326&biw=1470&bih=723&sxsrf=ANbL-n68xkf7rupxCnfQJmGSVa9MS1buSQ:1771314459815&gs_lp=Egxnd3Mtd2l6LXNlcnAiFmFic29sdXRlIGJhcmJlY3VlIGlub3IqAggAMgsQLhiABBjHARivATILEAAYgAQYkQIYigUyBRAAGIAEMgYQABgWGB4yBhAAGBYYHjIGEAAYFhgeMgYQABgWGB4yBhAAGBYYHjIGEAAYFhgeMgIQJjIaEC4YgAQYxwEYrwEYlwUY3AQY3gQY4ATYAQFIzDJQtQRYyidwBHgBkAEAmAG0AaABggmqAQMwLji4AQPIAQD4AQGYAgygAtsJwgIKEAAYsAMY1gQYR8ICDRAAGIAEGLADGEMYigXCAg4QABiwAxjkAhjWBNgBAcICGRAuGIAEGLADGNEDGEMYxwEYyAMYigXYAQHCAhkQLhiABBiwAxhDGMcBGMgDGIoFGK8B2AEBwgIKEAAYgAQYQxiKBcICDhAuGIAEGMcBGI4FGK8BwgIREC4YgAQYkQIYxwEYigUYrwHCAiAQLhiABBiRAhjHARiKBRivARiXBRjcBBjeBBjgBNgBAcICBRAhGKABwgINEC4YgAQYxwEYDRivAcICBxAAGIAEGA3CAggQABgIGA0YHsICCxAAGIAEGIYDGIoFwgIFEAAY7wXCAhwQLhiABBjHARgNGK8BGJcFGNwEGN4EGOAE2AEBmAMAiAYBkAYTugYGCAEQARgJkgcDNC44oAeugAGyBwMwLji4B7wJwgcHMS4wLjkuMsgHQ4AIAA&um=1&ie=UTF-8&fb=1&gl=in&sa=X&geocode=KUUVztpJkcs7MSEwyK3fMx0Z&daddr=T-02+fifth+floor,+Inorbit+Mall,+Software+Units+Layout,+Madhapur,+Hyderabad,+Telangana+500081 | U39: Mr. Suraj (Territory Manager) | V39: 9907958581 | W39: NA | X39: Kabir (Shift Manager) | Y39: 9121165812 | AA39: No | AT39: Doing 12-13 L daily revenue over all branches with Swiggy and Zomato. Maximum sale is of Combo Box : AOV 1200. Ala carte 500 | AU39: Yes | AV39: Introduction | AW39: Call Mr. Suraj | AX39: 46071 | AY39: 0.58333333 | AZ39: amit.kaler@capsdelivery.com | BA39: Cold Walk-in | BB39: Yes | BN39: Hi-Tech City | BP39: Absolute Barbeque
A40: 46070.561 | B40: 46069 | C40: 0.58333333 | D40: Intro Meeting | E40: Game Palacio | F40: 230 | G40: 1500 | H40: Na | J40: Tier-1(AOV>400) | K40: None | N40: 19 | O40: PVT | P40: Yes | Q40: Active | R40: Yes | S40: https://www.google.com/maps/dir//The+Game+Palacio,+Level+5,+Inorbit+Mall+Rd,+near+PVR+Cinema,+Software+Units+Layout,+HITEC+City,+Hyderabad,+Telangana+500081/@17.4391296,78.4859136,15z/data=!4m8!4m7!1m0!1m5!1m1!1s0x3bcb91b9b901e80d:0x5aebc4a84f5dfbba!2m2!1d78.3872005!2d17.4350874?entry=ttu&g_ep=EgoyMDI2MDIxMS4wIKXMDSoASAFQAw%3D%3D | U40: Mr. Reeshav (Business Head) | V40: 9867122223 | W40: reeshav@pjhindia.com | X40: Mr. Jeet | Y40: 8099420329 | AA40: No | AT40: Not available on Swiggy and Zomato looking for onboarding on online delivery platform, 19 outlets Pan India . Mr. Reeshav is the Business Head handle lead with care | AU40: Yes | AV40: Introduction | AW40: Message Mr. Reeshav get appointment, share proposal on Email | AX40: 46071 | AY40: 0.58333333 | AZ40: amit.kaler@capsdelivery.com | BA40: Cold Walk-in | BB40: Yes | BN40: Hi-Tech City | BP40: Game Palacio
...

Sheet Pivot Table 14

Sheet Visit New

Sheet POS Data
E1: ON BOARDED
E2: POS | F2: COUNTA of Date | G2: %
E3: PET POOJA | F3: 26 | G3: =F3/$F$10 -> 0.60465116
E4: Mobile Application | F4: 4 | G4: =F4/$F$10 -> 0.093023256
E5: Own | F5: 4 | G5: =F5/$F$10 -> 0.093023256
E6: NO POS | F6: 3 | G6: =F6/$F$10 -> 0.069767442
E7: Order matic | F7: 3 | G7: =F7/$F$10 -> 0.069767442
E8: Chef’s Desk | F8: 2 | G8: =F8/$F$10 -> 0.046511628
E9: urban pipers | F9: 1 | G9: =F9/$F$10 -> 0.023255814
E10: GT | F10: =SUM(F3:F9) -> 43 | G10: =F10/$F$10 -> 1
E12: Overall Data
E13: POS | F13: COUNTA of Date | G13: %
E14: Pet poja | F14: 85 | G14: =F14/$F$32 -> 0.69672131
E15: Own | F15: 5 | G15: =F15/$F$32 -> 0.040983607
E16: Brain power | F16: 4 | G16: =F16/$F$32 -> 0.032786885
E17: Mobile | F17: 4 | G17: =F17/$F$32 -> 0.032786885
E18: Not present | F18: 5 | G18: =F18/$F$32 -> 0.040983607
E19: Chef’s Desk | F19: 2 | G19: =F19/$F$32 -> 0.016393443
E20: MICROS | F20: 2 | G20: =F20/$F$32 -> 0.016393443
E21: Order matic | F21: 2 | G21: =F21/$F$32 -> 0.016393443
E22: OrderMatic | F22: 2 | G22: =F22/$F$32 -> 0.016393443
E23: Rista | F23: 2 | G23: =F23/$F$32 -> 0.016393443
E24: urban pipers | F24: 2 | G24: =F24/$F$32 -> 0.016393443
E25: Breeza (Exporex) | F25: 1 | G25: =F25/$F$32 -> 0.0081967213
... E31: Urban Piper | F31: 1 | G31: =F31/$F$32 -> 0.0081967213
E32: Total | F32: =sUM(F14:F31) -> 122

Sheet Data
A1: Date | B1: RM | C1: Restaurant | D1: REMARKS | E1: FOLLOW UP REQD. | F1: Follow up date | G1: Follow up Time | H1: =Form_Responses[[#HEADERS],[Points to be prepared]] -> Points to be prepared | I1: Onboarding Status | J1: Restaurant Category | K1: AOV | L1: Seating Capacity | M1: POC 1 | N1: POC 1 NUMBER | O1: POC 1 EMAIL ID | P1: POC 2 | Q1: POC 2 NUMBER | R1: POC 2 EMAIL ID | S1: =Form_Responses[[#HEADERS],[FSSAI]] -> FSSAI | T1: =Form_Responses[[#HEADERS],[GST]] -> GST | U1: =Form_Responses[[#HEADERS],[PAN Card]] -> PAN Card | V1: =Form_Responses[[#HEADERS],[Labour License]] -> Labour License | W1: =Form_Responses[[#HEADERS],[Menu (Image)]] -> Menu (Image) | X1: =Form_Responses[[#HEADERS],[Bank Account Proof]] -> Bank Account Proof | Y1: FSSAI Status | Z1: GST Status | AA1: PAN Card Status | AB1: Labour License Status | AC1: Menu Status | AD1: Bank Account Proof Status | AE1: =Form_Responses[[#HEADERS],[Name on Bank Account]] -> Name on Bank Account | AF1: =Form_Responses[[#HEADERS],[Owner Name]] -> Owner Name | AG1: =Form_Responses[[#HEADERS],[Owner Contact Number]] -> Owner Contact Number | AH1: =Form_Responses[[#HEADERS],[Owner Email address]] -> Owner Email address | AI1: =Form_Responses[[#HEADERS],[Legal Entity Name]] -> Legal Entity Name
A2: ='Form responses 1'!B4 -> 44577 | B2: ='Form responses 1'!AZ4 -> TEST | C2: ='Form responses 1'!BR4 -> 5823694 | D2: ='Form responses 1'!AT4 | E2: ='Form responses 1'!AU4 -> Yes | F2: ='Form responses 1'!AX4 -> 35098 | G2: ='Form responses 1'!AY4 -> 0.42430556 | H2: ='Form responses 1'!AW4 -> KBUHIH | I2: ='Form responses 1'!AS4 -> Yes | J2: ='Form responses 1'!J4 | K2: ='Form responses 1'!G4 | L2: ='Form responses 1'!F4 | M2: ='Form responses 1'!U4 -> sandeep | N2: ='Form responses 1'!V4 -> 916679555 | O2: ='Form responses 1'!W4 -> parul986@gmail | P2: ='Form responses 1'!X4 -> amit | Q2: ='Form responses 1'!Y4 -> 7896541232 | R2: ='Form responses 1'!Z4 -> parul@gmail | S2: ='Form responses 1'!AC4 -> https://drive.google.com/open?id=1K2GAYdf9j8OoeRQJN7a2rrWNqrJv-Yr8 | T2: ='Form responses 1'!AE4 -> https://drive.google.com/open?id=1Xrc3uPOk64pgUM1gMvRHq-hhYc6pYKJT | U2: ='Form responses 1'!AG4 -> https://drive.google.com/open?id=1P8o5u-wkGayDLIcyTArlaMzpPcBL8IP1 | V2: ='Form responses 1'!AI4 -> https://drive.google.com/open?id=1zOmxq565qkkMqqCAFCaCRWzjb7i60OTF | W2: ='Form responses 1'!AJ4 -> https://drive.google.com/open?id=1qsXvdJuct7_aToPR8ThIMJcmid9TRtyr | X2: ='Form responses 1'!AK4 | Y2: =if(S2>0,1,0) -> 1 | Z2: =if(T2>0,1,0) -> 1 | AA2: =if(U2>0,1,0) -> 1 | AB2: =if(V2>0,1,0) -> 1 | AC2: =if(W2>0,1,0) -> 1 | AD2: =if(X2>0,1,0) -> 0 | AE2: ='Form responses 1'!AN4 -> icici | AF2: ='Form responses 1'!AO4 -> jihughyfu | AG2: ='Form responses 1'!AP4 -> 64946165597 | AH2: ='Form responses 1'!AQ4 -> jhgyfyf2@GMAIL,COM | AI2: ='Form responses 1'!AR4 -> HVTFUGYFYGJH
