Workbook

Sheet Sheet1
A1: Date | B1: Restaurant Name | C1: RM/KAM | D1: Type of Ownership | E1: Address | F1: Signing Authority | G1: Pincode | H1: Locality | I1: Region | J1: Zone | K1: Service fees | L1: Service Fees Bucket | M1: Payment Gateway Charges | N1: Long Distance Charges % | O1: Legal Entity Name | P1: Legal Entity Address | Q1: Contact Person | R1: Phone no. | S1: Email ID | T1: Benficiary name | U1: Bank Name | V1: Account Number | W1: IFSC Code | X1: Account Type | Y1: FSSAI | Z1: GST | AA1: PAN | AB1: CHEQUE | AC1: MENU | AD1: LABOUR LINCENSE | AE1: Drive Link | AF1: Map Co-ordinates | AG1: LOCALITY AREA | AH1: Remarks | AI1: Remarks 2 | AJ1: Column 35 | AK1: Column 36 | AL1: Column 37 | AM1: Column 38 | AN1: Column 39 | AO1: Column 40 | AP1: Column 41 | AQ1: Column 42 | AR1: Column 43
A2: 46054 | B2: Mohammed minhaj uddin(Fancy Ice Cream) | C2: nitya.akshara@capsdelivery.com | D2: Proprietorship | E2: Rs complex vijayanagar colony near anjuman deendar back gate,masab tank,hyd | F2: Mohammed minhaj uddin | G2: 500057 | H2: Masab Tank | I2: =VLOOKUP(H2,Mapping!D:E,2,0) -> masab tank | J2: Zone 1 Mehdipatnam | K2: 0.22 | L2: =if(K2=0,"0",(if(K2<15%,"<15%",if(K2<17%,"<17%",IF(K2<20%,"<20%","20%+"))))) -> 20%+ | M2: 0.018 | O2: Mohammed minhaj uddin | P2: Rs complex vijayanagar colony near anjuman deendar back gate,masab tank,hyd 500057 | Q2: Mohammed minhaj uddin | R2: 9949583785 | S2: minhajsmarty@gmail.com | T2: Mohammed minhaj uddin | U2: Bank of Borada | V2: 75540100010283 | W2: BARBOVJVCHY | X2: Savings Account | Y2: Yes | Z2: No | AA2: Yes | AB2: No | AC2: No | AD2: No | AG2: =VLOOKUP(H:H,'Pivot Table 8'!B:C,2,0) -> #REF!
A3: 46054 | B3: R and B hospitality (Lebanese Grill) | C3: manasa.chigurupati@capsdelivery.com | D3: Partnership | E3: 12-2-825/2, Mehdipatnam | F3: M.A aqeel | G3: 500028 | H3: Mehdipatnam | I3: =VLOOKUP(H3,Mapping!D:E,2,0) -> mehdipatnam | J3: Zone 1 Mehdipatnam | K3: 0.24 | L3: =if(K3=0,"0",(if(K3<15%,"<15%",if(K3<17%,"<17%",IF(K3<20%,"<20%","20%+"))))) -> 20%+ | M3: 0.018 | O3: R and B hospitality | P3: 12-2-825/2, Mehdipatnam | Q3: M.A aqeel | R3: 9618659036 | S3: theoriginalgrill03@gmail.com | T3: not mentioned | U3: not mentioned | V3: not mentioned | W3: not mentioned | X3: No | Y3: No | Z3: No | AA3: No | AB3: No | AC3: No | AD3: NA | AE3: https://drive.google.com/drive/folders/1LEmpLQPhgga4iNmw8DK8oKC7Z9adVo_Z | AG3: =VLOOKUP(H:H,'Pivot Table 8'!B:C,2,0) -> #REF! | AI3: Not Uploaded
A4: 46054 | B4: Rahat Restaurant | C4: ankitha.baske@capsdelivery.com | D4: Proprietorship | E4: 12-2-486,4/7,Tappa Chabutra rd, asif nagar | F4: Mohammed Arshad | G4: 500006 | H4: Mehdipatnam | I4: =VLOOKUP(H4,Mapping!D:E,2,0) -> mehdipatnam | J4: Zone 1 Mehdipatnam | K4: 0.2 | L4: =if(K4=0,"0",(if(K4<15%,"<15%",if(K4<17%,"<17%",IF(K4<20%,"<20%","20%+"))))) -> 20%+ | M4: 0.018 | O4: Rahat Restaurant | P4: 12-2-486,4/7,Tappa Chabutra rd, asif nagar | Q4: Mohammed Arshad | R4: 8686561072 | S4: prinzzarshad@gamil.com | T4: Mohammed Arshad | U4: Airtel Bank | V4: 8686561072 | W4: AIRP0000001 | X4: Current Account | Y4: Yes | Z4: No | AA4: Yes | AB4: Yes | AC4: No | AD4: No | AG4: =VLOOKUP(H:H,'Pivot Table 8'!B:C,2,0) -> #REF! | AH4: switch off
A5: 46055 | B5: Alkemy | C5: manasa.chigurupati@capsdelivery.com | D5: Proprietorship | E5: kismatpur, survey 132,alkemy, 1/2 near prestige royal woods, abhyudaya nagar,dargah khaleejkhan | F5: Naika Amena | G5: 500086 | H5: Kismathpur | I5: =VLOOKUP(H5,Mapping!D:E,2,0) -> Langar Houz | J5: Zone 2 Jubliee hils | K5: 0.22 | L5: =if(K5=0,"0",(if(K5<15%,"<15%",if(K5<17%,"<17%",IF(K5<20%,"<20%","20%+"))))) -> 20%+ | M5: 0.018 | O5: alkemy | P5: survey 132,alkemy, 1/2 near prestige royal woods, abhyudaya nagar,dargah khaleejkhan | Q5: Naika Amena | R5: 8977918331 | S5: alkemy.ind@gmail.com | T5: alkemy | U5: Hdfc bank | V5: 50200096500839 | W5: HDFC0005853 | X5: Current Account | Y5: Yes | Z5: Yes | AA5: Yes | AB5: No | AC5: No | AD5: NA | AE5: https://drive.google.com/drive/folders/1hu60tEHn9OQubLStFBH50kklrc1mSCAQ | AG5: =VLOOKUP(H:H,'Pivot Table 8'!B:C,2,0) -> #REF! | AH5: Checked
A6: 46055 | B6: Begum ki briyani | C6: madhumitha.sonnakula@capsdelivery.com | D6: Proprietorship | E6: Attapur, Hyderabad | F6: Syed Ameer Hussain | G6: 500048 | H6: Attapur | I6: =VLOOKUP(H6,Mapping!D:E,2,0) -> mehdipatnam | J6: Zone 1 Mehdipatnam | K6: 0.22 | L6: =if(K6=0,"0",(if(K6<15%,"<15%",if(K6<17%,"<17%",IF(K6<20%,"<20%","20%+"))))) -> 20%+ | M6: 0.018 | O6: Tahaan foods private limited | P6: syno:32,plot no 7,pillar no 242,suleman nagar,attapur 500031 | Q6: Syed Ameer Hussain | R6: 8121007155 | S6: ameersyed131@gmail.com | T6: Shabana Begum | U6: Kotak mahindra bank | V6: 6049069572 | W6: KKBK0007487 | X6: Savings Account | Y6: Yes | Z6: NA | AA6: Yes | AB6: Yes | AC6: No | AD6: NA | AE6: https://drive.google.com/drive/folders/10dJbKX5ksSDh27Q6F7Vv--1oAZHBxtZz?usp=drive_link | AG6: =VLOOKUP(H:H,'Pivot Table 8'!B:C,2,0) -> #REF! | AH6: number does not exist
A7: 46055 | B7: Jusvous | C7: ankitha.baske@capsdelivery.com | D7: Proprietorship | E7: Attapur, Hyderabad | F7: Shabana Begum | G7: 500048 | H7: Attapur | I7: =VLOOKUP(H7,Mapping!D:E,2,0) -> mehdipatnam | J7: Zone 1 Mehdipatnam | K7: 0.22 | L7: =if(K7=0,"0",(if(K7<15%,"<15%",if(K7<17%,"<17%",IF(K7<20%,"<20%","20%+"))))) -> 20%+ | M7: 0.018 | O7: Jusvous | P7: syno:32,plot no 7,pillar no 242,suleman nagar,attapur 500030 | Q7: Shabana Begum | R7: 9701168269 | S7: shabanaameer131@gmail.com | T7: Shabana Begum | U7: Kotak mahindra bank | V7: 6049069572 | W7: KKBK0007487 | X7: Savings Account | Y7: Yes | Z7: NA | AA7: Yes | AB7: Yes | AC7: Yes | AD7: NA | AE7: https://drive.google.com/drive/folders/1HsJMgJiTpKMJBeM_QGp1o0L2blqry1_p?usp=drive_link | AG7: =VLOOKUP(H:H,'Pivot Table 8'!B:C,2,0) -> #REF!
A8: 46055 | B8: New farmaish Restaurant | C8: ankitha.baske@capsdelivery.com | D8: Proprietorship | E8: Banglaguda plot no 13/a bandlaguda,rahendranagar | F8: Syed Ameer Hussain | G8: 500091 | H8: Bandlaguda | I8: =VLOOKUP(H8,Mapping!D:E,2,0) -> mehdipatnam | J8: Zone 1 Mehdipatnam | K8: 0.22 | L8: =if(K8=0,"0",(if(K8<15%,"<15%",if(K8<17%,"<17%",IF(K8<20%,"<20%","20%+"))))) -> 20%+ | M8: 0.018 | O8: New farmaish Restaurant | P8: Banglaguda plot no 13/a banglaguda,rahendranagar,500091 | Q8: Syed Ameer Hussain | R8: 8121007155 | S8: ameersyed131@gmail.com | T8: Tahaan foods private limited | U8: Axis Bank | V8: 9.2100201e+15 | W8: UTIB0004826 | X8: coperate account | Y8: Yes | Z8: NA | AA8: Yes | AB8: Yes | AC8: No | AD8: NA | AE8: https://drive.google.com/drive/folders/1fCUi5DR9A9LINTfSuXKP6MhAbwgu-JhO?usp=drive_link | AG8: =VLOOKUP(H:H,'Pivot Table 8'!B:C,2,0) -> #REF!
A9: 46055 | B9: Waffle station | C9: manasa.chigurupati@capsdelivery.com | D9: Proprietorship | E9: survey no.37,himayath sagar village bandlaguda jagir muncipal corporation gandipet mandal | F9: Mohd Shoieb | G9: 500091 | H9: Gandipet | I9: =VLOOKUP(H9,Mapping!D:E,2,0) -> Langar Houz | J9: Zone 2 Jubliee hils | K9: 0.2 | L9: =if(K9=0,"0",(if(K9<15%,"<15%",if(K9<17%,"<17%",IF(K9<20%,"<20%","20%+"))))) -> 20%+ | M9: 0.018 | O9: Waffle station | P9: survey no.37,himayath sagar village bondlaguda jagir muncipal corporation gandipet mandal-500091 | Q9: Mohd Shoieb | R9: 9398554461 | S9: mmshoieb786@gmail.com | T9: Mohd Shoieb | U9: State Bank of India | V9: 20308200989 | W9: SBIN0008026 | X9: Savings Account | Y9: No | Z9: No | AA9: Yes | AB9: Yes | AC9: Yes | AD9: NA | AE9: https://drive.google.com/drive/folders/1ulPwAwYgA1k4f0sUZ1XbFUA0_rXx2Rcr | AG9: =VLOOKUP(H:H,'Pivot Table 8'!B:C,2,0) -> #REF! | AH9: Checked
A10: 46056 | B10: Al rawaf home made dishes | C10: madhumitha.sonnakula@capsdelivery.com | D10: Proprietorship | E10: Hakeem shah colony,tolichowki,hyderabad | F10: Asfiya sulthana | G10: 500008 | H10: Tolichowki | I10: =VLOOKUP(H10,Mapping!D:E,2,0) -> tolichowki | J10: Zone 2 Jubliee hils | K10: 0.22 | L10: =if(K10=0,"0",(if(K10<15%,"<15%",if(K10<17%,"<17%",IF(K10<20%,"<20%","20%+"))))) -> 20%+ | M10: 0.018 | O10: Al rawaf home made dishes | P10: Hakeem shah colony,tolichowki,hyderabad | Q10: Mohammed rizwan qureshi | R10: 8121586490 | S10: anasriyanmohammed@gmail.com | T10: Asfiya sulthana | U10: State Bank of India | V10: 42545548670 | W10: SBIN0005095 | X10: Savings Account | Y10: Yes | Z10: No | AA10: Yes | AB10: No | AC10: Yes | AD10: No | AE10: https://drive.google.com/drive/folders/1smCsR9G_YgZE_fKEqCXQq0ImYMzTeQTL | AG10: =VLOOKUP(H:H,'Pivot Table 8'!B:C,2,0) -> #REF!
A11: 46056 | B11: Bhojanams and biryani | C11: chanakya.inugala@capsdelivery.com | D11: Proprietorship | E11: plot no.87,swamy ayyappa society,madhapur,hyd | F11: Katragadda Shesha sai | G11: 500085 | H11: Madhapur | I11: =VLOOKUP(H11,Mapping!D:E,2,0) -> madhapur | J11: Zone 4 Hi-tech City | K11: 0.19 | L11: =if(K11=0,"0",(if(K11<15%,"<15%",if(K11<17%,"<17%",IF(K11<20%,"<20%","20%+"))))) -> <20% | M11: 0.018 | O11: M/s. invences foods Bhojanams and biryani | P11: plot no.87,swamy ayyappa society,madhapur,hyd,500085 | Q11: Katragadda Shesha sai | R11: 9052592437 | S11: sheshasai.katragadda@gmail.com | T11: Invences foods | U11: IDFC Bank | V11: 10192341683 | W11: IDFB0080231 | X11: Current Account | Y11: Yes | Z11: Yes | AA11: Yes | AB11: Yes | AC11: No | AD11: No | AF11: https://www.google.com/maps/place/Bhojanams+%26+Biryanis/@17.4468252,78.3895983,17z/data=!3m1!4b1!4m6!3m5!1s0x3bcb91687dc6785f:0x9d238a8fc18acf44!8m2!3d17.4468201!4d78.3921732!16s%2Fg%2F11fgjxmc9s?entry=ttu&g_ep=EgoyMDI2MDIxMS4wIKXMDSoASAFQAw%3D%3D | AG11: =VLOOKUP(H:H,'Pivot Table 8'!B:C,2,0) -> #REF!
A12: 46056 | B12: Bhuvan's kitchen | C12: manasa.chigurupati@capsdelivery.com | D12: Proprietorship | E12: H.no:6-331192/1/g/3 block-1 ground floor white house,kundanbagh,begumpet | F12: K.Rama Rao | G12: 500082 | H12: Begumpet | I12: =VLOOKUP(H12,Mapping!D:E,2,0) -> ameerpet | J12: Zone 6 Ameerpet | K12: 0.2 | L12: =if(K12=0,"0",(if(K12<15%,"<15%",if(K12<17%,"<17%",IF(K12<20%,"<20%","20%+"))))) -> 20%+ | M12: 0.018 | O12: Bhuvan's kitchen | P12: H.no:6-331192/1/g/3 block-1 ground floor white house,kundanbagh,begumpet,500082 | Q12: K.Rama Rao | R12: 9030611616 | S12: bhuvanskitchen25@gmail.com | T12: Ravindra babu tadiboyina | U12: Hdfc bank | V12: 50200102000231 | W12: HDFC0010090 | X12: Current Account | Y12: Yes | Z12: No | AA12: Yes | AB12: Yes | AC12: No | AD12: NA | AE12: https://drive.google.com/drive/folders/1KNPeVcsMJ0WDp5KH6nSS-MfsJEjo5gEl | AG12: =VLOOKUP(H:H,'Pivot Table 8'!B:C,2,0) -> #REF! | AH12: Checked
A13: 46056 | B13: Biryani N biryani | C13: ankitha.baske@capsdelivery.com | D13: Partnership | E13: 13-6-798/1/1,bapughat langa howz circle,13 hyd | F13: Raguveer | G13: 500008 | H13: Langer houz | I13: =VLOOKUP(H13,Mapping!D:E,2,0) -> Langar Houz | J13: Zone 2 Jubliee hils | K13: 0.22 | L13: =if(K13=0,"0",(if(K13<15%,"<15%",if(K13<17%,"<17%",IF(K13<20%,"<20%","20%+"))))) -> 20%+ | M13: 0.018 | O13: Biryani N biryani | P13: 13-6-798/1/1,bapughat langa howz circle,13 hyd | Q13: Raguveer | R13: 9963122625 | S13: munnoorraghuveer@gmail.com | T13: not mentioned | U13: not mentioned | V13: not mentioned | W13: not mentioned | X13: not mentioned | Y13: Yes | Z13: NA | AA13: Yes | AB13: No | AC13: Yes | AD13: NA | AE13: https://drive.google.com/drive/folders/1YsOVORTRLFpXHAUJiIrmFhshAi8DDIee?usp=drive_link | AG13: =VLOOKUP(H:H,'Pivot Table 8'!B:C,2,0) -> #REF! | AI13: Not Uploaded
A14: 46056 | B14: Bob's biryani | C14: manasa.chigurupati@capsdelivery.com | D14: Proprietorship | E14: 1-8-370and372 abhishek scan center,2nd floor near huda office,begumpet | F14: Paul kumar | G14: 500016 | H14: Begumpet | I14: =VLOOKUP(H14,Mapping!D:E,2,0) -> ameerpet | J14: Zone 6 Ameerpet | K14: 0.2 | L14: =if(K14=0,"0",(if(K14<15%,"<15%",if(K14<17%,"<17%",IF(K14<20%,"<20%","20%+"))))) -> 20%+ | M14: 0.018 | O14: Bob's biryani | P14: 1-8-370and372 abhishek scan center,2nd floor near huda office,begumpet,500016 | Q14: Paul kumar | R14: 9100777133 | S14: bobsbiriyani07@gmail.com | T14: Paul kumar rapaka | U14: Telangana state cooperative apex bank ltd | V14: 991111800000003 | W14: TSAB0000111 | X14: Current Account | Y14: Yes | Z14: NA | AA14: Yes | AB14: Yes | AC14: Yes | AD14: NA | AE14: https://drive.google.com/drive/folders/16PzSygeOLaXCa7wt2mKHTfEYFJ3Y9ChJ | AG14: =VLOOKUP(H:H,'Pivot Table 8'!B:C,2,0) -> #REF!
A15: 46056 | B15: Eastin hotels | C15: parthive.maganti@capsdelivery.com | D15: Partnership | E15: 2-52/1/3 hitech city rd,phase 2,kaveri hills madhapur,hyd | F15: Bargava.B | G15: 500081 | H15: Madhapur | I15: =VLOOKUP(H15,Mapping!D:E,2,0) -> madhapur | J15: Zone 4 Hi-tech City | K15: 0.15 | L15: =if(K15=0,"0",(if(K15<15%,"<15%",if(K15<17%,"<17%",IF(K15<20%,"<20%","20%+"))))) -> <17% | M15: 0.018 | O15: Eastin hotels | P15: 1-65-f,survey no.6,madhpur,gutlala begumpet,hyderabad,500081 | Q15: vamsi | R15: 9177285333 | S15: info@easrinhotels.in | T15: Eastin hotels and resorts | U15: ICICI BANK | V15: 112005003328 | W15: ICIC0001120 | X15: Current Account | Y15: Yes | Z15: Yes | AA15: Yes | AB15: Yes | AC15: Yes | AD15: No | AE15: Eastin Hotel | AF15: https://maps.app.goo.gl/7kDCtkQs6d4Hwruc8?g_st=iw | AG15: =VLOOKUP(H:H,'Pivot Table 8'!B:C,2,0) -> #REF! | AH15: checked
A16: 46056 | B16: Ns bakers | C16: akhila.narra@capsdelivery.com | D16: Proprietorship | E16: H.no:7-1-455/23/12,Ameerpet gurudwara road, telangana, | F16: Gardas saritha | G16: 500016 | H16: Ameerpet | I16: =VLOOKUP(H16,Mapping!D:E,2,0) -> panjagutta | J16: Zone 6 Ameerpet | K16: 0.22 | L16: =if(K16=0,"0",(if(K16<15%,"<15%",if(K16<17%,"<17%",IF(K16<20%,"<20%","20%+"))))) -> 20%+ | M16: 0.018 | O16: Ns bakers,Gardas saritha | P16: H.no:7-1-455/23/12,Ameerpet gurudwara road | Q16: Gardas saritha | R16: 9985000567 | S16: gardasnagesh34@gmail.com | T16: Gardas saritha | U16: State Bank of India | V16: 20297710024 | W16: SBIN0010676 | X16: Savings Account | AG16: =VLOOKUP(H:H,'Pivot Table 8'!B:C,2,0) -> #REF!
A17: 46056 | B17: Om Vaishnav Enterprise | C17: manasa.chigurupati@capsdelivery.com | D17: Proprietorship | E17: bus shelter stall,bus bay premises on sp road,opp anand theater and piller non1292, sindhi colony,begumpet | F17: Kuna Vaishnav | G17: 500003 | H17: Begumpet | I17: =VLOOKUP(H17,Mapping!D:E,2,0) -> ameerpet | J17: Zone 6 Ameerpet | K17: 0.22 | L17: =if(K17=0,"0",(if(K17<15%,"<15%",if(K17<17%,"<17%",IF(K17<20%,"<20%","20%+"))))) -> 20%+ | M17: 0.018 | O17: Om Vaishnav Enterprise | P17: bus shelter stall,bus bay premises on sp road,opp anand theater and piller non1292, sindhi colony,begumpet ,500003 | Q17: Kuna Vaishnav | R17: 9014176534 | S17: kunavyshnav@gmail.com | T17: Om Vaishnav Enterprise | U17: Yes Bank | V17: 100126900000171 | W17: YESB0001001 | X17: Current Account | Y17: Yes | Z17: Yes | AA17: Yes | AB17: Yes | AC17: Yes | AD17: NA | AE17: https://drive.google.com/drive/folders/1Bcpf2nTkRm8vyXXW6mpna2LwmGTtAnVJ | AG17: =VLOOKUP(H:H,'Pivot Table 8'!B:C,2,0) -> #REF! | AH17: Checked
A18: 46056 | B18: Pandu fast food center | C18: ankitha.baske@capsdelivery.com | D18: Proprietorship | E18: B41/f5 shop no.3 ps nagar,vijay nagar | F18: Yelgani sai kumar goud | G18: 500057 | H18: Mehdipatnam | I18: =VLOOKUP(H18,Mapping!D:E,2,0) -> mehdipatnam | J18: Zone 1 Mehdipatnam | K18: 0.22 | L18: =if(K18=0,"0",(if(K18<15%,"<15%",if(K18<17%,"<17%",IF(K18<20%,"<20%","20%+"))))) -> 20%+ | M18: 0.018 | O18: Yelgani sai kumar goud | P18: D.no: b41/f5 shop no.3 ps nagar,500057 | Q18: Yelgani sai kumar | R18: 9030518803 | S18: rebalsaikumargoud@gmail.com | T18: Yelgani sai kumar goud | U18: Centeal bank of india | V18: 3269632568 | W18: CBIN0283883 | X18: Savings Account | Y18: Yes | Z18: NA | AA18: Yes | AB18: No | AC18: Yes | AD18: NA | AE18: https://drive.google.com/drive/folders/16Pqgac9j1zbGysD70GA0bsI2nEml5nxG?usp=drive_link | AG18: =VLOOKUP(H:H,'Pivot Table 8'!B:C,2,0) -> #REF!
A19: 46056 | B19: Sunrise | C19: parthive.maganti@capsdelivery.com | D19: Proprietorship | E19: H.no:325/2rt,sanjeev reddy nagar,umeshchandra statue | F19: veeram reddy seetharam reddy | G19: 500038 | H19: S.R Nagar | I19: =VLOOKUP(H19,Mapping!D:E,2,0) -> panjagutta | J19: Zone 6 Ameerpet | K19: 0.17 | L19: =if(K19=0,"0",(if(K19<15%,"<15%",if(K19<17%,"<17%",IF(K19<20%,"<20%","20%+"))))) -> <20% | M19: 0.018 | O19: Sunrise | P19: H.no:325/2rt,sanjeev reddy nagar,umeshchandra statue road,s.r nagar hyd 500038 | Q19: veeram reddy seetharam reddy | R19: 8989873636 | S19: bowlrise.srnagaar@gmail.com | T19: For aarav sunrise hospitalitfes | U19: ICICI BANK | V19: 803705000004 | W19: ICIC0008037 | X19: Current Account | Y19: Yes | Z19: Yes | AA19: Yes | AB19: Yes | AC19: Yes | AD19: No | AE19: Sunrise Hotel | AF19: Sunrise Business Hotel | AG19: =VLOOKUP(H:H,'Pivot Table 8'!B:C,2,0) -> #REF! | AH19: checked
A20: 46056 | B20: Vaarahi fast food and tiffins | C20: greeshma.vanneldas@capsdelivery.com | D20: Proprietorship | E20: plot no.111,60ft road swamy ayyappa society,megha hills,khanamet,madhapur,hyd | F20: Divvela sri mahalakshmi | G20: 500081 | H20: Madhapur | I20: =VLOOKUP(H20,Mapping!D:E,2,0) -> madhapur | J20: Zone 4 Hi-tech City | K20: 0.22 | L20: =if(K20=0,"0",(if(K20<15%,"<15%",if(K20<17%,"<17%",IF(K20<20%,"<20%","20%+"))))) -> 20%+ | M20: 0.018 | O20: not mentioned | P20: plot no.111,60ft road swamy ayyappa society,megha hills,khanamet,madhapur,hyd | Q20: Prashanth | R20: 8555825704 | S20: not mentioned | T20: not mentioned | U20: not mentioned | V20: not mentioned | W20: not mentioned | X20: not mentioned | Y20: No | Z20: No | AA20: No | AB20: No | AC20: No | AD20: NA | AG20: =VLOOKUP(H:H,'Pivot Table 8'!B:C,2,0) -> #REF! | AH20: Today by EOD
A21: 46056 | B21: Zyras Biryani house | C21: moin.khan@capsdelivery.com | D21: Proprietorship | E21: plot no.03-805,shop no.2 ground floor M and M elite home,sri swamy ayyappa co-op Hs madhapur,hyd | F21: Natva Santosh kumar | G21: 500081 | H21: Madhapur | I21: =VLOOKUP(H21,Mapping!D:E,2,0) -> madhapur | J21: Zone 4 Hi-tech City | K21: 0.18 | L21: =if(K21=0,"0",(if(K21<15%,"<15%",if(K21<17%,"<17%",IF(K21<20%,"<20%","20%+"))))) -> <20% | M21: 0.018 | O21: Natva Santosh kumar | P21: plot no.03-805,shop no.2 ground floor M and M elite home,sri swamy ayyappa co-op Hs madhapur,hyd,500081 | Q21: Natva Santosh kumar | R21: 6302181276 | S21: nsantosh086@gmail.com | T21: Zyras Biryani house | U21: kotak mahindra bank | V21: 6450935473 | W21: KKBK0000561 | X21: Current Account | Y21: Yes | Z21: Yes | AA21: Yes | AB21: Yes | AC21: Yes | AD21: No | AE21: https://drive.google.com/drive/folders/1UCJPJOZGe8jeYMBocwtl6TwiAGnpIlby?usp=sharing | AG21: =VLOOKUP(H:H,'Pivot Table 8'!B:C,2,0) -> #REF!
A22: 46057 | B22: Alankrutha multi cuisine Restaurant | C22: moin.khan@capsdelivery.com | D22: proprietorship | E22: plot no-1206,madhapur,kondukur,rangareddy,telangana | F22: chatne akash | G22: 500081 | H22: Madhapur | I22: =VLOOKUP(H22,Mapping!D:E,2,0) -> madhapur | J22: Zone 4 Hi-tech City | K22: 0.2 | L22: =if(K22=0,"0",(if(K22<15%,"<15%",if(K22<17%,"<17%",IF(K22<20%,"<20%","20%+"))))) -> 20%+ | M22: 0.018 | O22: chatne akash | P22: plot no-1206,madhapur,kondukur,rangareddy,telangana,500081 | Q22: chatne akash | R22: 8341514984 | S22: cakash121@gmail.com | T22: Alankrutha multi cuisine Restaurant | U22: Bank of Borada | V22: 65980200001283 | W22: BARBODBMDHP | X22: Current Account | Y22: Yes | Z22: No | AA22: Yes | AB22: Yes | AC22: No | AD22: No | AE22: https://drive.google.com/drive/folders/1vjzFqzXaDbk0UgQjX9vk9TtWw7QA1ZRo?usp=drive_link | AG22: =VLOOKUP(H:H,'Pivot Table 8'!B:C,2,0) -> #REF!
A23: 46057 | B23: Alnkarutha multicusine Restaurant | C23: moin.khan@capsdelivery.com | D23: Proprietorship | E23: plot no.1206,madhapur,kandukur,rangareddy, telangana | F23: Chatne akash | G23: 500081 | H23: Madhapur | I23: =VLOOKUP(H23,Mapping!D:E,2,0) -> madhapur | J23: Zone 4 Hi-tech City | K23: 0.2 | L23: =if(K23=0,"0",(if(K23<15%,"<15%",if(K23<17%,"<17%",IF(K23<20%,"<20%","20%+"))))) -> 20%+ | M23: 0.018 | O23: Chatne akash | P23: plot no.1206,madhapur,kandukur,rangareddy, telangana-500081 | Q23: Chatne akash | R23: 8341514984 | S23: cakash121@gmail.com | T23: Alnkarutha multicusine Restaurant | U23: Bank of Borada | V23: 65980200001283 | W23: BARBODBMDHP | X23: Current Account | Y23: Yes | Z23: No | AA23: Yes | AB23: Yes | AC23: No | AD23: No | AE23: https://drive.google.com/drive/folders/1vjzFqzXaDbk0UgQjX9vk9TtWw7QA1ZRo?usp=drive_link | AG23: =VLOOKUP(H:H,'Pivot Table 8'!B:C,2,0) -> #REF!
A24: 46057 | B24: Ankapur Military Hotel Madhapur | C24: nitya.akshara@capsdelivery.com | I24: =VLOOKUP(H24,Mapping!D:E,2,0) -> #N/A | L24: =if(K24=0,"0",(if(K24<15%,"<15%",if(K24<17%,"<17%",IF(K24<20%,"<20%","20%+"))))) -> 0 | Y24: No | Z24: No | AA24: No | AB24: No | AC24: No | AD24: No | AG24: =VLOOKUP(H:H,'Pivot Table 8'!B:C,2,0) -> #REF! | AH24: Merchant asked to visit directly & explain the details.
A25: 46057 | B25: Ankapur village a military hotel | C25: nitya.akshara@capsdelivery.com | D25: LLP | E25: 1-98/2,durgam chervu,inorbit mall rd, hyd | F25: Ankapur village hotels llp | G25: 500081 | H25: Madhapur | I25: =VLOOKUP(H25,Mapping!D:E,2,0) -> madhapur | J25: Zone 4 Hi-tech City | K25: 0.15 | L25: =if(K25=0,"0",(if(K25<15%,"<15%",if(K25<17%,"<17%",IF(K25<20%,"<20%","20%+"))))) -> <17% | M25: 0.018 | O25: Ankapur village hotels llp | P25: H.no:1-89/2/1/21,plot no-10,21,21/a,21/a, sy no.37,38,39,40,46,47 to 49,inorbit mall road, madhapur | Q25: Venudhar reddy malakapalli | R25: 9642883377 | S25: venudharr@gmail.com | T25: Avhllp sambal | U25: Hdfc bank | V25: 50200029920971 | W25: HDFC0003739 | X25: Current Account | Y25: No | Z25: No | AA25: No | AB25: No | AC25: No | AD25: No | AG25: =VLOOKUP(H:H,'Pivot Table 8'!B:C,2,0) -> #REF! | AH25: Merchant asked to visit directly & explain the details.
A26: 46057 | B26: Ankapur village-a military hotel (kokapet) | C26: nitya.akshara@capsdelivery.com | D26: LLP | E26: osman sagar, kokapet gandipet, hyd,telangana | F26: Ankapur village hotels llp | G26: 500075 | H26: Gandipet | I26: =VLOOKUP(H26,Mapping!D:E,2,0) -> Langar Houz | J26: Zone 2 Jubliee hils | K26: 0.15 | L26: =if(K26=0,"0",(if(K26<15%,"<15%",if(K26<17%,"<17%",IF(K26<20%,"<20%","20%+"))))) -> <17% | M26: 0.018 | O26: A unit of Ankapur village hotels llp | P26: s.v no.167/1,madhuri sadan osman nagar road,opp ocean park kokapet hyd | Q26: Venudhar reddy | R26: 8121040277 | S26: not mentioned | T26: Avhllp kokapet | U26: Hdfc bank | V26: 50200093208670 | W26: HDFC0000021 | X26: Current Account | Y26: No | Z26: No | AA26: No | AB26: No | AC26: No | AD26: No | AG26: =VLOOKUP(H:H,'Pivot Table 8'!B:C,2,0) -> #REF! | AH26: Merchant asked to visit directly & explain the details.
A27: 46057 | B27: Govindas cafe | C27: madhumitha.sonnakula@capsdelivery.com | D27: Trust(company) | E27: plot no.220,mushak mahal residential, attapur,hyd | F27: Sachinandan hari das | G27: 500048 | H27: Attapur | I27: =VLOOKUP(H27,Mapping!D:E,2,0) -> mehdipatnam | J27: Zone 1 Mehdipatnam | K27: 0.21 | L27: =if(K27=0,"0",(if(K27<15%,"<15%",if(K27<17%,"<17%",IF(K27<20%,"<20%","20%+"))))) -> 20%+ | M27: 0.018 | O27: Govindas cafe | P27: plot no.220,mushak mahal residential complex huda,attapur,hyd | Q27: Sachinandan hari das | R27: 9392038004 | S27: admin.govindasatiskconattapur.com | T27: iskcon-Govindas | U27: Axis Bank | V27: 924010053814296 | W27: UTIB0004826 | X27: Current Account | Y27: Yes | Z27: Yes | AA27: Yes | AB27: Yes | AC27: Yes | AD27: No | AE27: https://drive.google.com/drive/folders/1dSwEyifkPxUG9QNgXPEPSPe9Wz37Yjpx | AG27: =VLOOKUP(H:H,'Pivot Table 8'!B:C,2,0) -> #REF!
A28: 46057 | B28: Guntur Mess | C28: greeshma.vanneldas@capsdelivery.com | D28: proprietorship | E28: manikonda, ayyappa society | F28: Siva Rama Krishna | G28: 500081 | H28: Manikonda | I28: =VLOOKUP(H28,Mapping!D:E,2,0) -> manikonda | J28: Zone 3 Raidurg | K28: 0.22 | L28: =if(K28=0,"0",(if(K28<15%,"<15%",if(K28<17%,"<17%",IF(K28<20%,"<20%","20%+"))))) -> 20%+ | M28: 0.018 | O28: not mentioned | P28: not mentioned | Q28: Siva Rama Krishna | R28: 9391167117 | S28: shivakandavelli@gmail.com | T28: Kandavelli Siva Rama Krishna | U28: Unioun bank of india | V28: 135610011001804 | W28: UBIN0813567 | X28: Savings Account | Y28: No | Z28: No | AA28: No | AB28: No | AC28: No | AD28: NA | AG28: =VLOOKUP(H:H,'Pivot Table 8'!B:C,2,0) -> #REF! | AH28: Today bt eod
A29: 46057 | B29: Lassi corner | C29: madhumitha.sonnakula@capsdelivery.com | D29: Proprietorship | E29: plot no 7,syno 17 ground floor R.R district 500047 | F29: Ashok thapa,Vishu thapa | G29: 500047 | H29: Gandipet | I29: =VLOOKUP(H29,Mapping!D:E,2,0) -> Langar Houz | J29: Zone 2 Jubliee hils | L29: =if(K29=0,"0",(if(K29<15%,"<15%",if(K29<17%,"<17%",IF(K29<20%,"<20%","20%+"))))) -> 0 | M29: 0.018 | O29: Lassi corner | P29: plot no 7 ground floor,gandamguda 500045 | Q29: Ashok thapa | R29: 7995109409 | S29: vishnuthapaa@gmail.com | T29: not mentioned | U29: not mentioned | V29: not mentioned | W29: not mentioned | X29: not mentioned | Y29: Yes | Z29: No | AA29: Yes | AB29: No | AC29: No | AD29: No | AG29: =VLOOKUP(H:H,'Pivot Table 8'!B:C,2,0) -> #REF!
A30: 46057 | B30: Lassi corner | C30: nitya.akshara@capsdelivery.com | D30: LLP | E30: h.no:1-98/6a/14,plot no 42 road no.3, patrikanagar hitech city,madhapur, hitech city | F30: venudhar reddy | G30: 500075 | H30: Madhapur | I30: =VLOOKUP(H30,Mapping!D:E,2,0) -> madhapur | J30: Zone 4 Hi-tech City | K30: 0.15 | L30: =if(K30=0,"0",(if(K30<15%,"<15%",if(K30<17%,"<17%",IF(K30<20%,"<20%","20%+"))))) -> <17% | M30: 0.018 | O30: Ankapur village-A military hotel | P30: h.no:1-98/6a/14,plot no 42 road no.3, patrikanagar hitech city,madhapur, hitech city | Q30: venudhar reddy | R30: 7995854986 | S30: venudharr@gmail.com | T30: Avhllp military hotel | U30: Hdfc bank | V30: 50200029918240 | W30: HDFC0003739 | X30: Current Account | Y30: No | Z30: No | AA30: No | AB30: No | AC30: No | AD30: No | AG30: =VLOOKUP(H:H,'Pivot Table 8'!B:C,2,0) -> #REF! | AH30: Merchant asked to visit directly & explain the details.
A31: 46057 | B31: Namaste the Indian kitchen | C31: greeshma.vanneldas@capsdelivery.com | D31: Partnership | E31: plot no. 501,sy no.11/14.11/15,11/16,khanamet village ayyappa society,htd | F31: not mentioned | G31: 500084 | H31: Madhapur | I31: =VLOOKUP(H31,Mapping!D:E,2,0) -> madhapur | J31: Zone 4 Hi-tech City | K31: 0.2 | L31: =if(K31=0,"0",(if(K31<15%,"<15%",if(K31<17%,"<17%",IF(K31<20%,"<20%","20%+"))))) -> 20%+ | M31: 0.018 | O31: V6 ventures LLP | P31: Bulding no/Flat no, sy no.64, mindspace road, madhapur | Q31: Raghav | R31: 9972901941 | S31: V6 venturesllp@gmail.com | T31: V6 ventures LLP | U31: ICICI BANK | V31: 4005030744 | W31: ICIC0000040 | X31: Current Account | Y31: Yes | Z31: Yes | AA31: Yes | AB31: Yes | AC31: Yes | AD31: NA | AG31: =VLOOKUP(H:H,'Pivot Table 8'!B:C,2,0) -> #REF! | AH31: Anexure Missing
A32: 46057 | B32: Rayalaseema spice Restaurant | C32: moin.khan@capsdelivery.com | D32: Proprietorship | E32: plot no.1208,g1andg2,ground floor,ayyappa society,madhapur,hyd,telangan | F32: Pokuri prathyusha | G32: 500081 | H32: Madhapur | I32: =VLOOKUP(H32,Mapping!D:E,2,0) -> madhapur | J32: Zone 4 Hi-tech City | K32: 0.18 | L32: =if(K32=0,"0",(if(K32<15%,"<15%",if(K32<17%,"<17%",IF(K32<20%,"<20%","20%+"))))) -> <20% | M32: 0.018 | O32: Pokuri prathyusha | P32: plot no.1208,g1andg2,ground floor,ayyappa society,madhapur,hyd,telangan,500081 | Q32: Narupu reddy | R32: 6301782448 | S32: rayalaseemaspicefamilyvetaura@gmail.com | T32: Rayalaseema spice Restaurant | U32: Bandhan Bank | V32: 20100061259823 | W32: BDBL0002722 | X32: Current Account | Y32: No | Z32: No | AA32: Yes | AB32: No | AC32: No | AD32: No | AE32: https://drive.google.com/drive/folders/1O9zT56Qjx_Fn-1HXs44MbW70lNaEY6eu?usp=sharing | AG32: =VLOOKUP(H:H,'Pivot Table 8'!B:C,2,0) -> #REF! | AH32: not answering calls
A33: 46057 | B33: Rolo one Bakers | C33: moin.khan@capsdelivery.com | D33: Partnership | E33: p.no.4(a),1-89/8/4, madhapur ,hyd,telangana | F33: Ragavendra Gm | G33: 500081 | H33: Madhapur | I33: =VLOOKUP(H33,Mapping!D:E,2,0) -> madhapur | J33: Zone 4 Hi-tech City | K33: 0.17 | L33: =if(K33=0,"0",(if(K33<15%,"<15%",if(K33<17%,"<17%",IF(K33<20%,"<20%","20%+"))))) -> <20% | M33: 0.018 | O33: Rolo one Bakers | P33: p.no.4(a),1-89/8/4, madhapur ,hyd,telangana,500081 | Q33: Ragavendra Gm | R33: 9963968917 | S33: raghavs2606@yahoo.com | T33: Muni Ragavendra gandavadi | U33: Central Bank Of India | V33: 5684056323 | W33: CBIN0280814 | X33: Current Account | Y33: Yes | Z33: Yes | AA33: Yes | AB33: Yes | AC33: No | AD33: No | AE33: https://drive.google.com/drive/folders/1fMxi-4kuAYVRCumBpHT0cJ0OQJGZKWP9?usp=sharing | AG33: =VLOOKUP(H:H,'Pivot Table 8'!B:C,2,0) -> #REF!
A34: 46057 | B34: Shree balaji tiffin center | C34: ankitha.baske@capsdelivery.com | D34: Proprietorship | E34: 4-17-12,hitech city santosh residency,beside farmaish Restaurant,gandamguda,hyd | F34: B.Raja yashwanth kumar | G34: 500081 | H34: Gandamguda | I34: =VLOOKUP(H34,Mapping!D:E,2,0) -> mehdipatnam | J34: Zone 1 Mehdipatnam | K34: 0.22 | L34: =if(K34=0,"0",(if(K34<15%,"<15%",if(K34<17%,"<17%",IF(K34<20%,"<20%","20%+"))))) -> 20%+ | M34: 0.018 | O34: Shree balaji tiffin center | P34: 4-17-12,hitech city santosh residency,hyd | Q34: B.Raja yashwanth kumar | R34: 9705812524 | S34: yeshwanth.bugude@gmail.com | T34: B.Raja yashwanth kumar | U34: Bank of Borada | V34: 80980100003622 | W34: BARBOVJBUND | X34: Savings Account | Y34: Yes | Z34: NA | AA34: Yes | AB34: Yes | AC34: Yes | AD34: NA | AG34: =VLOOKUP(H:H,'Pivot Table 8'!B:C,2,0) -> #REF!
A35: 46057 | B35: Shri balaji family dhaba | C35: ankitha.baske@capsdelivery.com | D35: Proprietorship | E35: Gudi malkapur,12-2-417/46/9,sharada nagar colony gudimalk | F35: Bidhaniyasoni | G35: 500028 | H35: Gudimalkapur | I35: =VLOOKUP(H35,Mapping!D:E,2,0) -> masab tank | J35: Zone 1 Mehdipatnam | K35: 0.22 | L35: =if(K35=0,"0",(if(K35<15%,"<15%",if(K35<17%,"<17%",IF(K35<20%,"<20%","20%+"))))) -> 20%+ | M35: 0.018 | O35: Shri balaji family dhaba | P35: 12-2-417/46/9,sharada nagar colony gudimalk,500028 | Q35: Rihaan | R35: 04023536061 | S35: bighaniyasony@gmail.com | T35: B.soni | U35: DCB bank | V35: ;02711500006880 | W35: DCBL0000027 | X35: Savings Account | Y35: Yes | Z35: NA | AA35: Yes | AB35: Yes | AC35: Yes | AD35: Yes | AG35: =VLOOKUP(H:H,'Pivot Table 8'!B:C,2,0) -> #REF!
A36: 46057 | B36: Sri Udupi grand pure veg | C36: madhumitha.sonnakula@capsdelivery.com | D36: proprietorship | E36: Gudimalkapur, hyderabad 13-6-460/112, mahesh nagar gudimalkapur | F36: Manjunath | G36: 500028 | H36: Gudimalkapur | I36: =VLOOKUP(H36,Mapping!D:E,2,0) -> masab tank | J36: Zone 1 Mehdipatnam | K36: 0.22 | L36: =if(K36=0,"0",(if(K36<15%,"<15%",if(K36<17%,"<17%",IF(K36<20%,"<20%","20%+"))))) -> 20%+ | M36: 0.018 | O36: Sri Udupi grand pure veg | P36: 13-6-460/112, mahesh nagar gudimalkapur | Q36: Manjunath | R36: 9032944860 | S36: bmanjunathkotteri@gmail.com | T36: Bailu Manjunath | U36: City union bank ltd | V36: 500101013048225 | W36: CIUB0000386 | X36: Savings Account | Y36: Yes | Z36: No | AA36: Yes | AB36: Yes | AC36: Yes | AD36: No | AE36: https://drive.google.com/drive/folders/1feNNzyCdx3sxbzFyqJhVyFJNTvoq8k2G | AG36: =VLOOKUP(H:H,'Pivot Table 8'!B:C,2,0) -> #REF!
A37: 46057 | B37: Vidhusekhara pizzeria | C37: greeshma.vanneldas@capsdelivery.com | D37: Pvt ltd | E37: plot no.o1,first floor survey no,12 kondapur village serlingampally circle | F37: Madyapaga Ravindra | G37: 500019 | H37: Kondapur | I37: =VLOOKUP(H37,Mapping!D:E,2,0) -> Kondapur | J37: Zone 5 Kukatpally | K37: 0.22 | L37: =if(K37=0,"0",(if(K37<15%,"<15%",if(K37<17%,"<17%",IF(K37<20%,"<20%","20%+"))))) -> 20%+ | M37: 0.018 | O37: Vidhusekhara pizzeria private limited | P37: plot no.o1,first floor survey no,12 kondapur village serlingampally circle,500019 | Q37: Grandi sravan kumar | R37: 7347337323 | S37: vidhusekharapizzeria@gmail.com | T37: Vidhusekhara pizzeria private limited | U37: Unioun bank of india | V37: 226711010000044 | W37: UBIN0822671 | X37: Current Account | Y37: Yes | Z37: Yes | AA37: Yes | AB37: Yes | AC37: Yes | AD37: NA | AG37: KONDAPUR | AH37: just menu pending will receive today
A38: 46057 | B38: Vrindaas kitchen | C38: greeshma.vanneldas@capsdelivery.com | D38: Proprietorship | E38: shopon plot no.2a in sy no 2a in sy no.12, situated at 500084 | F38: Abhilash Thota | G38: 500084 | H38: Kondapur | I38: =VLOOKUP(H38,Mapping!D:E,2,0) -> Kondapur | J38: Zone 5 Kukatpally | K38: 0.22 | L38: =if(K38=0,"0",(if(K38<15%,"<15%",if(K38<17%,"<17%",IF(K38<20%,"<20%","20%+"))))) -> 20%+ | M38: 0.018 | O38: Vrindaas kitchen | P38: shopon plot no.2a in sy no 2a in sy no.12, situated at 500084 | Q38: Abhilash Thota | R38: 7416814310 | S38: abhigupta143@gmail.com | T38: Thota abhilash | U38: RBL Bank | V38: 309005434613 | W38: RATN000208 | X38: Savings Account | Y38: Yes | Z38: No | AA38: Yes | AB38: Yes | AC38: Yes | AD38: NA | AG38: KONDAPUR | AH38: All done
A39: 46058 | B39: Ahladha kitchen | C39: greeshma.vanneldas@capsdelivery.com | D39: Partnership | E39: plot no 68,shop no 5,Ayyappa society main road,madhapur,serlingampally circle no20 hyd | F39: Penubua kula sai | G39: 500081 | H39: Madhapur | I39: =VLOOKUP(H39,Mapping!D:E,2,0) -> madhapur | J39: Zone 4 Hi-tech City | K39: 0.2 | L39: =if(K39=0,"0",(if(K39<15%,"<15%",if(K39<17%,"<17%",IF(K39<20%,"<20%","20%+"))))) -> 20%+ | M39: 0.018 | O39: Ahladha kitchen | P39: plot no-68 shop no-5 ayyappa socity circle-20 hyd,500081 | Q39: naveen | R39: 9849975158 | S39: ahladha2025@gmail.com | T39: Ahladha kitchen | U39: Induslnd Bank | V39: 259849975158 | W39: INDB0001805 | X39: not mentioned | Y39: Yes | Z39: Yes | AA39: Yes | AB39: Yes | AC39: No | AD39: Yes | AG39: =VLOOKUP(H:H,'Pivot Table 8'!B:C,2,0) -> #REF! | AH39: menu pending
A40: 46058 | B40: Flavours of biryani cafe | C40: madhumitha.sonnakula@capsdelivery.com | D40: Proprietorship | E40: 6-1-964,shop no 2, khairthabad circel, no.17 | F40: Mangalarapu sai teja | G40: 500004 | H40: Khairathabad | I40: =VLOOKUP(H40,Mapping!D:E,2,0) -> Khairathabad | J40: Zone 1 Mehdipatnam | K40: 0.22 | L40: =if(K40=0,"0",(if(K40<15%,"<15%",if(K40<17%,"<17%",IF(K40<20%,"<20%","20%+"))))) -> 20%+ | M40: 0.018 | O40: Mangalarapu sai teja | P40: 6-1-964,shop no 2, khairthabad circel, no.17,hyderabad telangana500004 | Q40: Mangalarapu sai teja | R40: 9642897117 | S40: flavourbiryanicafe@gmail.com | T40: M. sai teja | U40: Indian bank | V40: 6414081002 | W40: IDIB000k284 | X40: Savings Account | Y40: Yes | Z40: No | AA40: Yes | AB40: Yes | AC40: Yes | AD40: No | AE40: https://drive.google.com/drive/folders/1XNX_PCNBMLG34jK7wyR_ALjgQ6bEz51m | AG40: =VLOOKUP(H:H,'Pivot Table 8'!B:C,2,0) -> #REF!
...

Sheet whatsapp
A1: Date | B1: Restaurant name | C1: location | D1: poc name | E1: contact no. | F1: person went | G1: comment | H1: Follow up date | I1: Follow up time | J1: Google links | K1: Column 11 | L1: Column 12 | M1: Column 13 | N1: Column 14 | O1: Column 15 | P1: Column 16 | Q1: Column 17 | R1: Column 18 | S1: Column 19 | T1: Column 20 | U1: Column 21 | V1: Column 22 | W1: Column 23 | X1: Column 24 | Y1: Column 25 | Z1: Column 26
A2: 46062 | B2: Beyniaz shawarm | C2: Ameerpet | D2: tarun | E2: 7981194980 | F2: sumadhur | G2: Today 4pm
A3: 46062 | B3: Pachakattu dosa | D3: mukesh | E3: 7992492924 | F3: moin.khan@capsdelivery.com | G3: Tommorow
A4: 46062 | B4: cake factory | C4: Ameerpet | E4: 8712274005 | F4: sumadhur | G4: owner will get back
A5: 46062 | B5: SSR FOOD zone | F5: ankitha.baske@capsdelivery.com | G5: onboarded
A6: 46062 | B6: 1000 Biryani | C6: Somajiguda | F6: madhumitha.sonnakula@capsdelivery.com | G6: onboarded
A7: 46062 | B7: Pondy parottas | F7: manasa.chigurupati@capsdelivery.com | G7: owner available after 2pm
A8: 46062 | B8: Roti Ruchulu | C8: Kukatpally | F8: ankitha.baske@capsdelivery.com | G8: Discuss with the partner
A9: 46062 | B9: Bojam taiyaru | F9: madhumitha.sonnakula@capsdelivery.com | G9: intersted will get back to us tomorrow by 6pm
A10: 46062 | B10: Vela bites | D10: Akhil Reddy | E10: 9059810130 | F10: chanakya.inugala@capsdelivery.com | G10: meet on wednesday for onboarding
A11: 46062 | B11: Bowls and Bites | C11: Kukatpally | F11: ankitha.baske@capsdelivery.com | G11: owner will be available after 2 to 3 hours
A12: 46062 | B12: Hari Balaji Dhaba | C12: Ameerpet | E12: 9985559231 | F12: sumadhur | G12: owner will get back
A13: 46062 | B13: Pappanam | D13: Sai Krishna | F13: chanakya.inugala@capsdelivery.com | G13: meet tomorrow sai krishna
A14: 46062 | B14: Grand Spicy Bawarchi | D14: Muqeeb | E14: 970526974 | F14: moin.khan@capsdelivery.com | G14: owner not available
A15: 46062 | B15: The Good Sparrow Millests food | C15: Kondapur/miyapur/Chandanagar | F15: parthive.maganti@capsdelivery.com | G15: onboarded 3 oulets
A16: 46062 | B16: Babai Hotel | D16: Dinesh reddy | F16: chanakya.inugala@capsdelivery.com | G16: he will meet after a week
A17: 46062 | B17: Abhiruchi Biryani | F17: manasa.chigurupati@capsdelivery.com | G17: will be onboarding tommorow
A18: 46062 | B18: Kshatriya Grand | C18: Kukatpally | F18: ankitha.baske@capsdelivery.com | G18: onboarded
A19: 46062 | B19: Mehfil Restaurant | D19: Anil | E19: 8121020121 | F19: moin.khan@capsdelivery.com | G19: will be available on wednesday
A20: 46062 | B20: Bakeway Bakers | C20: Ameerpet | F20: sumadhur | G20: onboarded
A21: 46062 | B21: mandi@36 arabian kitchen | F21: madhumitha.sonnakula@capsdelivery.com | G21: meet owner at banjara hills in evenig times
A22: 46062 | B22: Darbar Family | F22: manasa.chigurupati@capsdelivery.com | G22: owner will available tomorrow at 12pm
A23: 46062 | B23: The Bougainvillea | C23: Jubliee Hills | F23: akhila.narra@capsdelivery.com | G23: intersted he need a trail run once with our app
A24: 46062 | B24: Toppa | F24: madhumitha.sonnakula@capsdelivery.com | G24: manager wiil be available after 4pm
A25: 46062 | B25: The Hole In The Wall Cafe | F25: madhumitha.sonnakula@capsdelivery.com | G25: we can meet tomorrow
A26: 46062 | B26: Kshatriya Grand | C26: Kukatpally | F26: ankitha.baske@capsdelivery.com | G26: he needs lesser cpmmission than 17%
A27: 46062 | B27: Concu | E27: 9985800031 | F27: madhumitha.sonnakula@capsdelivery.com | G27: they will get back to us as they want detailed in everthing
A28: 46062 | B28: Brown Bear | C28: Kukatpally | D28: Manoj | E28: 7077577025 | F28: ankitha.baske@capsdelivery.com | G28: he will talk with MD and get back tomorrow
A29: 46062 | B29: 99 Pancake | F29: madhumitha.sonnakula@capsdelivery.com | G29: interstead get back tomorrow
A30: 46062 | B30: Rivora the cafe | C30: kukatpally | F30: manasa.chigurupati@capsdelivery.com | G30: onboarded
A31: 46062 | B31: Nasir | E31: 8886904546 | F31: chanakya.inugala@capsdelivery.com | G31: as documents not available in this branch going to onboard tomorrow
A32: 46062 | B32: Coffee Place | F32: manasa.chigurupati@capsdelivery.com | G32: interseted get back tomorrow
A33: 46062 | B33: Veeramagearu vantillu | F33: ankitha.baske@capsdelivery.com | G33: onboarded
A34: 46062 | B34: Bhadrakali hotel | C34: Ameerpet | E34: 9949256290 | F34: sumadhur | G34: owner will get back tomorrow
A35: 46062 | B35: Mokshi kitchen | C35: Kondapur | F35: parthive.maganti@capsdelivery.com | G35: onboarded
A36: 46062 | B36: North indian hub only veg | C36: Kondapur | F36: parthive.maganti@capsdelivery.com | G36: onboarded
A37: 46062 | B37: Kavya Tiffins | F37: akhila.narra@capsdelivery.com | G37: tomorrow morning will be onboarded
A38: 46062 | B38: Heart cup coffee | C38: Kondapur | F38: parthive.maganti@capsdelivery.com | G38: meeting fixed at 6pm
A39: 46062 | B39: Deccan chillis | C39: Ameerpet | F39: sumadhur | G39: meeting tomorrow with the owner
A40: 46062 | B40: Lassi Store | C40: Ameerpet | F40: sumadhur | G40: the owner is free after 8pm
...

Sheet Pivot Table 28
A34: Region | B34: COUNTA of Region
A35: ameerpet | B35: 18
A36: banjara hills | B36: 3
A37: begumpet | B37: 10
A38: Borabanda | B38: 1
A39: gachibowli | B39: 20
A40: hafeezpet | B40: 12
A41: Hitech-City | B41: 19
A42: Hyderabad | B42: 2
A43: Jubliee hills | B43: 12
A44: Khairathabad | B44: 14
A45: Kondapur | B45: 40
A46: KPHP | B46: 3
... A62: yousufguda | B62: 28
A63: #N/A | B63: 4
B64: 0

Sheet Pivot Table 27

Sheet Mapping
A1: Location | B1: Zone | H1: Zone | I1: Region | J1: Onboarding Done
A2: Khairathabad | B2: Zone 1 Mehdipatnam | D2: locality | E2: Location | F2: Zone | H2: Mehipatnam Zone 1 | I2: Khairathabad | J2: =iferror(VLOOKUP(I2,'Pivot Table 11'!B:C,2,0),0) -> 17
A3: Masab Tank | B3: Zone 1 Mehdipatnam | D3: secunderabad | E3: begumpet | F3: Hyderabad | I3: Masab Tank | J3: =iferror(VLOOKUP(I3,'Pivot Table 11'!B:C,2,0),0) -> 6
A4: Mehdipatnam | B4: Zone 1 Mehdipatnam | D4: Hyderabad | E4: Hyderabad | F4: Hyderabad | I4: Mehdipatnam | J4: =iferror(VLOOKUP(I4,'Pivot Table 11'!B:C,2,0),0) -> 39
A5: Banjara Hills | B5: Zone 1 Mehdipatnam | D5: not mentioned | E5: not mentioned | F5: NA | I5: Banjara Hills | J5: =iferror(VLOOKUP(I5,'Pivot Table 11'!B:C,2,0),0) -> 3
A6: Tolichowki | B6: Zone 2 Jubliee hils | D6: Secundrabad | E6: Secundrabad | F6: Secundrabad | H6: Jubilee Hills Zone 2 | I6: Tolichowki | J6: =iferror(VLOOKUP(I6,'Pivot Table 11'!B:C,2,0),0) -> 4
A7: Langar Houz | B7: Zone 2 Jubliee hils | D7: secundrabad | E7: Secundrabad | F7: Secundrabad | I7: Langar Houz | J7: =iferror(VLOOKUP(I7,'Pivot Table 11'!B:C,2,0),0) -> 16
A8: Hakimpet | B8: Zone 2 Jubliee hils | D8: Banglaguda | E8: mehdipatnam | F8: =VLOOKUP(E8,A:B,2,0) -> Zone 1 Mehdipatnam | I8: Hakimpet | J8: =iferror(VLOOKUP(I8,'Pivot Table 11'!B:C,2,0),0) -> 0
A9: Jubilee Hills | B9: Zone 2 Jubliee hils | D9: Attapur | E9: mehdipatnam | F9: =VLOOKUP(E9,A:B,2,0) -> Zone 1 Mehdipatnam | I9: Jubilee Hills | J9: =iferror(VLOOKUP(I9,'Pivot Table 11'!B:C,2,0),0) -> 0
A10: Shaikpet | B10: Zone 3 Raidurg | D10: khairathabad | E10: masab tank | F10: =VLOOKUP(E10,A:B,2,0) -> Zone 1 Mehdipatnam | H10: Raidurg Zone 3 | I10: Shaikpet | J10: =iferror(VLOOKUP(I10,'Pivot Table 11'!B:C,2,0),0) -> 3
A11: Manikonda | B11: Zone 3 Raidurg | D11: Mehdipatnam | E11: mehdipatnam | F11: =VLOOKUP(E11,A:B,2,0) -> Zone 1 Mehdipatnam | I11: Manikonda | J11: =iferror(VLOOKUP(I11,'Pivot Table 11'!B:C,2,0),0) -> 34
A12: Raidurg | B12: Zone 3 Raidurg | D12: Asif nagar | E12: mehdipatnam | F12: =VLOOKUP(E12,A:B,2,0) -> Zone 1 Mehdipatnam | I12: Raidurg | J12: =iferror(VLOOKUP(I12,'Pivot Table 11'!B:C,2,0),0) -> 2
A13: Narsingi | B13: Zone 3 Raidurg | D13: Gudimalkapur | E13: masab tank | F13: =VLOOKUP(E13,A:B,2,0) -> Zone 1 Mehdipatnam | I13: Narsingi | J13: =iferror(VLOOKUP(I13,'Pivot Table 11'!B:C,2,0),0) -> 0
A14: Nanakramguda | B14: Zone 3 Raidurg | D14: Khairathabad | E14: Khairathabad | F14: =VLOOKUP(E14,A:B,2,0) -> Zone 1 Mehdipatnam | I14: Nanakramguda | J14: =iferror(VLOOKUP(I14,'Pivot Table 11'!B:C,2,0),0) -> 10
A15: Madhapur | B15: Zone 4 Hi-tech City | D15: Masab Tank | E15: masab tank | F15: =VLOOKUP(E15,A:B,2,0) -> Zone 1 Mehdipatnam | H15: HI-Tech Zone 4 | I15: Madhapur | J15: =iferror(VLOOKUP(I15,'Pivot Table 11'!B:C,2,0),0) -> 45
A16: Gachibowli | B16: Zone 4 Hi-tech City | D16: Banjara Hills | E16: banjara hills | F16: =VLOOKUP(E16,A:B,2,0) -> Zone 1 Mehdipatnam | I16: Gachibowli | J16: =iferror(VLOOKUP(I16,'Pivot Table 11'!B:C,2,0),0) -> 20
A17: Hitech-City | B17: Zone 4 Hi-tech City | D17: Gandamguda | E17: mehdipatnam | F17: =VLOOKUP(E17,A:B,2,0) -> Zone 1 Mehdipatnam | I17: Hitech-City | J17: =iferror(VLOOKUP(I17,'Pivot Table 11'!B:C,2,0),0) -> 19
A18: Sherilingampally | B18: Zone 5 Kukatpally | D18: Himayahnagar | E18: Khairathabad | F18: =VLOOKUP(E18,A:B,2,0) -> Zone 1 Mehdipatnam | H18: Kukatpally Zone 5 | I18: Sherilingampally | J18: =iferror(VLOOKUP(I18,'Pivot Table 11'!B:C,2,0),0) -> 8
A19: Hafeezpet | B19: Zone 5 Kukatpally | D19: Lakdikapool | E19: masab tank | F19: =VLOOKUP(E19,A:B,2,0) -> Zone 1 Mehdipatnam | I19: Hafeezpet | J19: =iferror(VLOOKUP(I19,'Pivot Table 11'!B:C,2,0),0) -> 12
A20: kukatpally | B20: Zone 5 Kukatpally | D20: Tappa | E20: mehdipatnam | F20: =VLOOKUP(E20,A:B,2,0) -> Zone 1 Mehdipatnam | I20: kukatpally | J20: =iferror(VLOOKUP(I20,'Pivot Table 11'!B:C,2,0),0) -> 89
A21: Kondapur | B21: Zone 5 Kukatpally | D21: Bandlaguda | E21: mehdipatnam | F21: =VLOOKUP(E21,A:B,2,0) -> Zone 1 Mehdipatnam | I21: Kondapur | J21: =iferror(VLOOKUP(I21,'Pivot Table 11'!B:C,2,0),0) -> 40
A22: Miyapur | B22: Zone 5 Kukatpally | D22: Kismatpur | E22: mehdipatnam | F22: =VLOOKUP(E22,A:B,2,0) -> Zone 1 Mehdipatnam | I22: Miyapur | J22: =iferror(VLOOKUP(I22,'Pivot Table 11'!B:C,2,0),0) -> 65
A23: Moosapet | B23: Zone 6 Ameerpet | D23: Gandipet | E23: Langar Houz | F23: =VLOOKUP(E23,A:B,2,0) -> Zone 2 Jubliee hils | H23: Ameerpet Zone 6 | I23: Moosapet | J23: =iferror(VLOOKUP(I23,'Pivot Table 11'!B:C,2,0),0) -> 0
A24: Ameerpet | B24: Zone 6 Ameerpet | D24: Kismathpur | E24: Langar Houz | F24: =VLOOKUP(E24,A:B,2,0) -> Zone 2 Jubliee hils | I24: Ameerpet | J24: =iferror(VLOOKUP(I24,'Pivot Table 11'!B:C,2,0),0) -> 18
A25: Panjagutta | B25: Zone 6 Ameerpet | D25: Langer houz | E25: Langar Houz | F25: =VLOOKUP(E25,A:B,2,0) -> Zone 2 Jubliee hils | I25: Panjagutta | J25: =iferror(VLOOKUP(I25,'Pivot Table 11'!B:C,2,0),0) -> 1
A26: Yousufguda | B26: Zone 6 Ameerpet | D26: Tolichowki | E26: tolichowki | F26: =VLOOKUP(E26,A:B,2,0) -> Zone 2 Jubliee hils | I26: Yousufguda | J26: =iferror(VLOOKUP(I26,'Pivot Table 11'!B:C,2,0),0) -> 28
A27: Erragada | B27: Zone 6 Ameerpet | D27: Manikonda | E27: manikonda | F27: =VLOOKUP(E27,A:B,2,0) -> Zone 3 Raidurg | I27: Erragada | J27: =iferror(VLOOKUP(I27,'Pivot Table 11'!B:C,2,0),0) -> 0
A28: Borabonda | B28: Zone 6 Ameerpet | D28: Nanakramguda | E28: nanakramguda | F28: =VLOOKUP(E28,A:B,2,0) -> Zone 3 Raidurg | I28: Borabonda | J28: =iferror(VLOOKUP(I28,'Pivot Table 11'!B:C,2,0),0) -> 0
D29: shaikpet | E29: shaikpet | F29: =VLOOKUP(E29,A:B,2,0) -> Zone 3 Raidurg | J29: =sum(J2:J28) -> 479
D30: Narsingi | E30: Nanakramguda | F30: =VLOOKUP(E30,A:B,2,0) -> Zone 3 Raidurg
D31: Madhapur | E31: madhapur | F31: =VLOOKUP(E31,A:B,2,0) -> Zone 4 Hi-tech City
D32: Gachibowli | E32: gachibowli | F32: =VLOOKUP(E32,A:B,2,0) -> Zone 4 Hi-tech City
D33: Hitech city | E33: Hitech-City | F33: =VLOOKUP(E33,A:B,2,0) -> Zone 4 Hi-tech City
D34: Kothaguda | E34: Hitech-City | F34: =VLOOKUP(E34,A:B,2,0) -> Zone 4 Hi-tech City
D35: Kukatpally | E35: kukatpally | F35: =VLOOKUP(E35,A:B,2,0) -> Zone 5 Kukatpally
D36: Miyapur | E36: miyapur | F36: =VLOOKUP(E36,A:B,2,0) -> Zone 5 Kukatpally
D37: Chandanagar | E37: miyapur | F37: =VLOOKUP(E37,A:B,2,0) -> Zone 5 Kukatpally
D38: serlingampally | E38: hafeezpet | F38: =VLOOKUP(E38,A:B,2,0) -> Zone 5 Kukatpally
D39: Hafeezpet | E39: kukatpally | F39: =VLOOKUP(E39,A:B,2,0) -> Zone 5 Kukatpally
D40: KPHB | E40: miyapur | F40: =VLOOKUP(E40,A:B,2,0) -> Zone 5 Kukatpally
...

Sheet Pivot Table 25
B403: COUNTA of Address
A404: Grand Total | B404: 548
A405: not mentioned | B405: 34
A406: Ragiv gandhi nagar,langarhouz,hyderabad,telangana | B406: 14
A407: H.no:2-106/9/1,krisat colony,phase-4,gangaram chandanagar | B407: 9
A408: plot no.103 KSR, Enclave beside ayyappa swamy temple,chandanagar | B408: 7
A409: will- Mallipaathi po -malipathi, 210-C Sri Ram Kondapur | B409: 6
A410: 138/1,flat no 45 sham apt,secunderabad 138/1,flat no 45 shama apt sindi colony pg road | B410: 5
A411: h.no:8-3-229/D175,ventatagiri,yousufguda,hyd,telangana | B411: 5
A412: High tension,line rd,raghavendra colony,kondapur,telangana | B412: 5
A413: plot no.13,sipa paradise,pragathi nagar | B413: 5
A414: plot no.410,raja reshwara nagar,kondapur,serlingampally | B414: 5
A415: sy no.38,39,40,khanmet village,serlingampally circle no.20,hyd | B415: 5
... A800: Yadagiri nagar rd,Jawahar nagar,yousfguda,khairthabad circle no.17,hyd | B800: 1
B801: 0

Sheet Pivot Table 24
B477: COUNTA of Restaurant Name
A478: Grand Total | B478: 500
A479: Aroma Cafe | B479: 4
A480: Sreeja's home foods | B480: 4
A481: D and D caterers | B481: 3
A482: Dosarani Chethivanta | B482: 3
A483: New Chanti mess | B483: 3
A484: P.K Food court | B484: 3
A485: Sangam family dhaba | B485: 3
A486: Sri shakambhari Restaurant | B486: 3
A487: Tealogy cafe | B487: 3
A488: The good sparrow | B488: 3
A489: Chai kaburlu | B489: 2
... A941: Zyras Biryani house | B941: 1
B942: 0

Sheet Pivot Table 22

Sheet Pivot Table 23
B1390: COUNTA of Restaurant name
B1391: 0
A1392: 7 sauces | B1392: 1
A1393: A1 bawarchi | B1393: 1
A1394: A1 hotel | B1394: 1
A1395: Aha Bhojanam | B1395: 1
A1396: Aha Dakshin | B1396: 1
A1397: Al saba Restaurant | B1397: 1
A1398: Anandobhrahma | B1398: 1
A1399: Andhra bhavan | B1399: 1
A1400: AR Raghavendra tiffins and meals | B1400: 1
A1401: Audio Cup | B1401: 1
A1402: B.Bichareddy Pure ghee sweets & cookies | B1402: 1
A1403: Bakers harvest | B1403: 1
... A2776: Grand Total | B2776: 1506

Sheet Pivot Table 21

Sheet total
E2: Date | F2: COUNTA of Date
F3: 0
E4: 46054 | F4: 3
E5: 46055 | F5: 5
E6: 46056 | F6: 12
E7: 46057 | F7: 16
E8: 46058 | F8: 9
E9: 46059 | F9: 8
E10: 46060 | F10: 1
E11: 46062 | F11: 22
E12: 46063 | F12: 3
E13: 46064 | F13: 8
E14: 46065 | F14: 16
E15: 46066 | F15: 19
... E27: 46079 | F27: 15
E28: Grand Total | F28: 356
C33: Date | E33: 46054 | F33: 46055 | G33: 46056 | H33: 46057 | I33: 46058 | J33: 46059 | K33: 46060 | L33: 46062 | M33: 46063 | N33: 46064 | O33: 46065 | P33: 46066 | Q33: 46067 | R33: 46069 | S33: 46070 | T33: 46071 | U33: 46072 | V33: 46073 | W33: 46074 | X33: 46075 | Y33: 46076 | Z33: 46077 | AA33: 46078 | AB33: 46079 | AC33: Grand Total
C34: COUNTA of Date | D34: 0 | E34: 3 | F34: 5 | G34: 12 | H34: 16 | I34: 9 | J34: 8 | K34: 1 | L34: 22 | M34: 3 | N34: 8 | O34: 16 | P34: 19 | Q34: 4 | R34: 24 | S34: 15 | T34: 25 | U34: 27 | V34: 17 | W34: 9 | X34: 1 | Y34: 22 | Z34: 19 | AA34: 56 | AB34: 15 | AC34: 356

Sheet Pivot Table 16
B45: Region | C45: COUNTA of Region | E45: Zone 4 Hi-tech City | F45: gachibowli | G45: 18
C46: 0 | F46: Hitech-City | G46: 12
B47: Borabanda | C47: 1 | F47: madhapur | G47: 35
B48: Hyderabad | C48: 1 | E48: Zone 4 Hi-tech City Total | G48: 65
A49: Total | C49: 2 | E49: Zone 5 Kukatpally | F49: hafeezpet | G49: 2
A50: Zone 1 Mehdipatnam | B50: banjara hills | C50: 2 | F50: Kondapur | G50: 20
B51: Hyderabad | C51: 1 | F51: KPHP | G51: 3
B52: Khairathabad | C52: 10 | F52: kukatpally | G52: 48
B53: Langar Houz | C53: 16 | F53: miyapur | G53: 22
B54: masab tank | C54: 6 | F54: panjagutta | G54: 1
B55: mehdipatnam | C55: 35 | F55: Sherilingampally | G55: 8
A56: Zone 1 Mehdipatnam Total | C56: 70 | E56: Zone 5 Kukatpally Total | G56: 104
A57: Zone 2 Jubliee hils | B57: Jubliee hills | C57: 3 | E57: Zone 6 Ameerpet | F57: ameerpet | G57: 16
B58: Langar Houz | C58: 18 | F58: begumpet | G58: 9
B59: tolichowki | C59: 4 | F59: panjagutta | G59: 15
A60: Zone 2 Jubliee hils Total | C60: 25 | F60: yousufguda | G60: 23
A61: Zone 3 Raidurg | B61: manikonda | C61: 28 | E61: Zone 6 Ameerpet Total | G61: 63
B62: nanakramguda | C62: 9 | E62: #N/A | F62: Hyderabad | G62: 1
B63: shaikpet | C63: 3 | E63: #N/A Total | G63: 1
A64: Zone 3 Raidurg Total | C64: 40 | E64: Grand Total | G64: 370

Sheet Sheet13

Sheet Sheet11
A2: Zone | B2: Region | C2: COUNTA of Region | E2: Zone 4 Hi-tech City | F2: gachibowli | G2: 18
C3: 0 | F3: Hitech-City | G3: 12
B4: Borabanda | C4: 1 | F4: madhapur | G4: 35
B5: Hyderabad | C5: 1 | E5: Zone 4 Hi-tech City Total | G5: 65
A6: Total | C6: 2 | E6: Zone 5 Kukatpally | F6: hafeezpet | G6: 2
A7: Zone 1 Mehdipatnam | B7: banjara hills | C7: 2 | F7: Kondapur | G7: 20
B8: Hyderabad | C8: 1 | F8: KPHP | G8: 3
B9: Khairathabad | C9: 10 | F9: kukatpally | G9: 48
B10: Langar Houz | C10: 16 | F10: miyapur | G10: 22
B11: masab tank | C11: 6 | F11: panjagutta | G11: 1
B12: mehdipatnam | C12: 35 | F12: Sherilingampally | G12: 8
A13: Zone 1 Mehdipatnam Total | C13: 70 | E13: Zone 5 Kukatpally Total | G13: 104
A14: Zone 2 Jubliee hils | B14: Jubliee hills | C14: 3 | E14: Zone 6 Ameerpet | F14: ameerpet | G14: 16
B15: Langar Houz | C15: 18 | F15: begumpet | G15: 9
B16: tolichowki | C16: 4 | F16: panjagutta | G16: 15
A17: Zone 2 Jubliee hils Total | C17: 25 | F17: yousufguda | G17: 23
A18: Zone 3 Raidurg | B18: manikonda | C18: 28 | E18: Zone 6 Ameerpet Total | G18: 63
B19: nanakramguda | C19: 9 | E19: #N/A | F19: Hyderabad | G19: 1
B20: shaikpet | C20: 3 | E20: #N/A Total | G20: 1
A21: Zone 3 Raidurg Total | C21: 40 | E21: Grand Total | G21: 370

Sheet Pivot Table 13

Sheet Sheet10
A1: RM/KAM | C1: 46076 | G1: KAM | H1: RM/ KAM Name | I1: Onboarding done on 23rd | J1: Contract received | K1: Pending Contracts
B2: 0 | G2: manasa.chigurupati@capsdelivery.com | H2: chanakya.inugala@capsdelivery.com | I2: 0 | J2: =VLOOKUP(H2,A:C,3,0) | K2: =I2-J2 -> 0
B3: 0 | G3: manisha.kumari@capsdelivery.com | H3: parthive.maganti@capsdelivery.com | I3: 12 | J3: =VLOOKUP(H3,A:C,3,0) -> 12 | K3: =I3-J3 -> 0
A4: akhila.narra@capsdelivery.com | G4: manisha.kumari@capsdelivery.com | H4: sumadhur.mummadi@capsdelivery.com | I4: 2 | J4: =VLOOKUP(H4,A:C,3,0) -> 1 | K4: =I4-J4 -> 1
A5: ankitha.baske@capsdelivery.com | C5: 2 | G5: anisha.poddar@capsdelivery.com | H5: greeshma.vanneldas@capsdelivery.com | J5: =VLOOKUP(H5,A:C,3,0) | K5: =I5-J5 -> 0
A6: chanakya.inugala@capsdelivery.com | G6: akhila.narra@capsdelivery.com | H6: madhumitha.sonnakula@capsdelivery.com | I6: 0 | J6: =VLOOKUP(H6,A:C,3,0) | K6: =I6-J6 -> 0
A7: greeshma.vanneldas@capsdelivery.com | G7: akhila.narra@capsdelivery.com | H7: akhila.narra@capsdelivery.com | I7: 0 | J7: =VLOOKUP(H7,A:C,3,0) | K7: =I7-J7 -> 0
A8: madhumitha.sonnakula@capsdelivery.com | G8: manisha.kumari@capsdelivery.com | H8: anisha.poddar@capsdelivery.com | J8: 0 | K8: =I8-J8 -> 0
A9: manasa.chigurupati@capsdelivery.com | G9: manisha.kumari@capsdelivery.com | H9: Srivani.reddy@capsdelivery.com | I9: 2 | J9: =VLOOKUP(H9,A:C,3,0) | K9: =I9-J9 -> 2
A10: moin.khan@capsdelivery.com | G10: manasa.chigurupati@capsdelivery.com | H10: manasa.chigurupati@capsdelivery.com | I10: 0 | J10: =VLOOKUP(H10,A:C,3,0) | K10: =I10-J10 -> 0
A11: nitya.akshara@capsdelivery.com | C11: 3 | G11: manasa.chigurupati@capsdelivery.com | H11: ankitha.baske@capsdelivery.com | I11: 2 | J11: =VLOOKUP(H11,A:C,3,0) -> 2 | K11: =I11-J11 -> 0
A12: parthive.maganti@capsdelivery.com | C12: 12 | G12: akhila.narra@capsdelivery.com | H12: moin.khan@capsdelivery.com | I12: 2 | J12: =VLOOKUP(H12,A:C,3,0) | K12: =I12-J12 -> 2
A13: Srivani.reddy@capsdelivery.com | G13: amit.kaler@capsdelivery.com | H13: manisha.kumari@capsdelivery.com | I13: 0 | J13: 0 | K13: =I13-J13 -> 0
A14: sumadhur.mummadi@capsdelivery.com | C14: 1 | G14: manasa.chigurupati@capsdelivery.com | H14: nitya.akshara@capsdelivery.com | I14: 3 | J14: =VLOOKUP(H14,A:C,3,0) -> 3 | K14: =I14-J14 -> 0
A15: Grand Total | B15: 0 | C15: 18 | I15: =sUM(I3:I14) -> 23 | J15: =sUM(J3:J14) -> 18 | K15: =sUM(K3:K14) -> 5

Sheet Pivot Table 11

Sheet Detail12-Zone 4 Hi-tech City-Hi
A1: Date | B1: Restaurant Name | C1: RM/KAM | D1: Type of Ownership | E1: Address | F1: Signing Authority | G1: Pincode | H1: Locality | I1: Region | J1: Zone
A2: 46072 | B2: Punjabi Chaska | C2: greeshma.vanneldas@capsdelivery.com | D2: Proprietorship | E2: h.no 1-90/c/8, inside sri krishna food court, hudo techno enclave, opp LP tower, vittalrao nagar, hitech city | F2: Angad Singh | G2: 500081 | H2: Hitech city | I2: Hitech-City | J2: Zone 4 Hi-tech City
A3: 46073 | B3: Mickey's Tiffin | C3: parthive.maganti@capsdelivery.com | D3: Partnership | E3: Plot No. 279 27/a, khanamet village, Hi-tech city. Seringampally near SSR on the way drive in , Seringampally | F3: not mentioned | G3: 500081 | H3: HItech City | I3: Hitech-City | J3: Zone 4 Hi-tech City
A4: 46073 | B4: Sravanti Biryani | C4: parthive.maganti@capsdelivery.com | D4: Proprietorship | E4: HNO No. 2-41/11/10/11, G3, Sri sai shanti residency prashanth nagar, kothaguda circle | F4: Manoj Reddy | G4: 500084 | H4: Kothaguda | I4: Hitech-City | J4: Zone 4 Hi-tech City
A5: 46073 | B5: Sravanti Fast Food | C5: parthive.maganti@capsdelivery.com | D5: Proprietorship | E5: Door No, 2-41/11/10/, G3, Sri sai residancy prashanth nagar, kothaguda circle | F5: Manoj Reddy | G5: 500084 | H5: Kothaguda | I5: Hitech-City | J5: Zone 4 Hi-tech City
A6: 46073 | B6: Sravanti Mess | C6: parthive.maganti@capsdelivery.com | D6: Proprietorship | E6: Door No, 2-41/11/10/, G3, Sri sai residancy prashanth nagar, kothaguda | F6: Manoj Reddy | G6: 500084 | H6: Kothaguda | I6: Hitech-City | J6: Zone 4 Hi-tech City
A7: 46073 | B7: Sravanti Tiffins | C7: parthive.maganti@capsdelivery.com | D7: Proprietorship | E7: Door No, 2-41/11/10/, G3, Sri sai residancy prashanth nagar, kothaguda circle | F7: Manoj Reddy | G7: 500084 | H7: Kothaguda | I7: Hitech-City | J7: Zone 4 Hi-tech City
A8: 46074 | B8: Snacking Cafe Private limited | C8: parthive.maganti@capsdelivery.com | D8: Proprietorship | E8: RHS-R6-UE, Near Nift college, Hitech city metro chanda nagar Circle No 21, HYD | F8: not mentioned | G8: 500081 | H8: Hitech City | I8: Hitech-City | J8: Zone 4 Hi-tech City
A9: 46074 | B9: Sravanam 4am Biryani | C9: parthive.maganti@capsdelivery.com | D9: Proprietorship | E9: Plot No. 35, khampet , Hitech city, Chandanagar circle No. 21, Hyderbad | F9: not mentioned | G9: 500019 | H9: HItech City | I9: Hitech-City | J9: Zone 4 Hi-tech City
A10: 46074 | B10: Sravanam 4am kuska | C10: parthive.maganti@capsdelivery.com | D10: partnership | E10: plot no.35,khanmet,chandanagar circle no.21 | F10: not mentioned | G10: 500019 | H10: Hitech City | I10: Hitech-City | J10: Zone 4 Hi-tech City
A11: 46077 | B11: Avacado on wheels | C11: parthive.maganti@capsdelivery.com | D11: proprietorship | E11: shop no.1,patrika nagar,SLR guest house,selingampally circle no.20,hyd | F11: not mentioned | G11: 500081 | H11: Hitech City | I11: Hitech-City | J11: Zone 4 Hi-tech City
A12: 46077 | B12: Charcoal sahwarma | C12: parthive.maganti@capsdelivery.com | D12: Proprietorship | E12: shop no.1,patrika nagar,SLR guest house,selingampally circle no.20,hyd | F12: not mentioned | G12: 500081 | H12: Hitech City | I12: Hitech-City | J12: Zone 4 Hi-tech City
A13: 46077 | B13: Oh My Momo's | C13: parthive.maganti@capsdelivery.com | D13: proprietorship | E13: shop no.1,patrika nagar,SLR guest house,selingampally circle no.20,hyd | F13: not mentioned | G13: 500081 | H13: Hitech City | I13: Hitech-City | J13: Zone 4 Hi-tech City
... A20: 46091 | B20: Sri Venkateshwara Hospitality | C20: parthive.maganti@capsdelivery.com | D20: proprietorship | E20: 2-91/14/8,whitefeilds,kondapur,hitech city,serlingampally circle no.20,telangana | F20: not mentioned | G20: 500084 | H20: Hitech City | I20: Hitech-City | J20: Zone 4 Hi-tech City

Sheet Visits

Sheet Agreement Collected

Sheet Detail9-10022026
A1: Date | B1: Name of Restaurant | C1: RM/ KAM | D1: Type of enity | E1: Address | F1: Authorized signatory | G1: locality | H1: Zone | I1: Service Fee in % | J1: Service Fees Bucket | K1: Payment Gateway Charges | L1: Long Distance Charges | M1: legal entity name | N1: legal entity address | O1: contact person | P1: phone number | Q1: Email | R1: Benficiary name | S1: Bank name | T1: Account number | U1: IFSC code | V1: Account type | W1: FSSAI | X1: GST | Y1: PAN | Z1: CHEQUE | AA1: MENU | AB1: LABOUR LICENCE | AC1: Drive Link | AD1: Map Co-ordinates | AE1: Column 3 | AF1: Column 4 | AG1: Column 5 | AH1: Column 6 | AI1: Column 7 | AJ1: Column 8 | AK1: Column 9 | AL1: Column 10 | AM1: Column 11 | AN1: Column 12 | AO1: Column 13 | AP1: Column 14
